Workbook

Sheet 深睡枕PRO 2.0
C2: 时间 | D2: 45492 | E2: 45493 | F2: 45494 | G2: 45495 | H2: 45496 | I2: 45497 | J2: 45498 | K2: 45499 | L2: 45500 | M2: 45501 | N2: 45502 | O2: 45503 | P2: 45504 | Q2: 45505 | R2: 45506 | S2: 45507 | T2: 45508 | U2: 45509 | V2: 45510 | W2: 45511 | X2: 45512 | Y2: 45513 | Z2: 45514 | AA2: 45515 | AB2: 45516 | AC2: 45517 | AD2: 45518 | AE2: 45519 | AF2: 45520 | AG2: 45521 | AH2: 45522 | AI2: 45523 | AJ2: 45524 | AK2: 45525 | AL2: 45526 | AM2: 45527 | AN2: 45528 | AO2: 45529 | AP2: 45530 | AQ2: 45531 | AR2: 45532 | AS2: 45533 | AT2: 45534 | AU2: 45535 | AV2: 45536 | AW2: 45537 | AX2: 45538 | AY2: 45539 | AZ2: 45540 | BA2: 45541 | BB2: 45542 | BC2: 45543 | BD2: 45544 | BE2: 45545 | BF2: 45546 | BG2: 45547 | BH2: 45548 | BI2: 45549 | BJ2: 45550 | BK2: 45551 | BL2: 45552 | BM2: 45553 | BN2: 45554 | BO2: 45555 | BP2: 45556 | BQ2: 45557 | BR2: 45558 | BS2: 45559 | BT2: 45560 | BU2: 45561 | BV2: 45562 | BW2: 45563 | BX2: 45564 | BY2: 45565 | BZ2: 45566 | CA2: 45567 | CB2: 45568 | CC2: 45569 | CD2: 45570 | CE2: 45571 | CF2: 45572 | CG2: 45573 | CH2: 45574 | CI2: 45575 | CJ2: 45576 | CK2: 45577 | CL2: 45578 | CM2: 45579 | CN2: 45580 | CO2: 45581 | CP2: 45582 | CQ2: 45583 | CR2: 45584 | CS2: 45585 | CT2: 45586 | CU2: 45587 | CV2: 45588 | CW2: 45589 | CX2: 45590 | CY2: 45591 | CZ2: 45592 | DA2: 45593 | DB2: 45594 | DC2: 45595 | DD2: 45596 | DE2: 45597 | DF2: 45598 | DG2: 45599 | DH2: 45600 | DI2: 45601 | DJ2: 45602 | DK2: 45603 | DL2: 45604 | DM2: 45605 | DN2: 45606 | DO2: 45607 | DP2: 45608 | DQ2: 45609 | DR2: 45610 | DS2: 45611 | DT2: 45612 | DU2: 45613 | DV2: 45614 | DW2: 45615 | DX2: 45616 | DY2: 45617 | DZ2: 45618 | EA2: 45619 | EB2: 45620 | EC2: 45621 | ED2: 45622 | EE2: 45623 | EF2: 45624 | EG2: 45625 | EH2: 45626 | EI2: 45627 | EJ2: 45628 | EK2: 45629 | EL2: 45630 | EM2: 45631 | EN2: 45632 | EO2: 45633 | EP2: 45634 | EQ2: 45635 | ER2: 45636 | ES2: 45637 | ET2: 45638 | EU2: 45639
A3: 128000269031621 | B3: 成品到货计划 | C3: 预估到货量 | E3: 1000 | F3: 0 | G3: 0 | H3: 0 | I3: 4000 | J3: 4500 | K3: 4500 | L3: 5000 | M3: 5500 | N3: 4500 | O3: 4000 | P3: 7000 | Q3: 7500 | R3: 8500 | S3: 9000 | T3: 9000 | U3: 9000 | V3: 9000 | W3: 12000 | X3: 12000 | Y3: 12000 | Z3: 9000 | AA3: 12000 | AB3: 12000 | AC3: 5800 | AD3: 11200 | AE3: 5800 | AF3: 11200 | AG3: 5800 | AH3: 11200 | AI3: 5800 | AJ3: 11200 | AK3: 5800 | AL3: 11200 | AM3: 5800 | AN3: 11200 | AO3: 11200 | AP3: 5800 | AQ3: 11200 | AR3: 5800 | AS3: 11200 | AT3: 5800 | AU3: 11200 | AV3: 5800 | AW3: 11200 | AX3: 5800 | AY3: 11200 | AZ3: 11200 | BA3: 5800 | BB3: 11200 | BC3: 5800 | BD3: 11200 | BE3: 5800 | BF3: 11200 | BG3: 11200 | BH3: 11200 | BI3: 11200 | BJ3: 11200 | BK3: 11200 | BL3: 11200 | BM3: 11200 | BN3: 11200 | BO3: 11200 | BP3: 11200 | BQ3: 11200 | BR3: 11200 | BS3: 11200 | BT3: 16800 | BU3: 16800 | BV3: 11200 | BW3: 11200 | BX3: 16800 | BY3: 16800 | BZ3: 16800 | CA3: 0 | CB3: 0 | CC3: 0 | CD3: 0 | CE3: 0 | CF3: 0 | CG3: 11600 | CH3: 5800 | CI3: 5800 | CJ3: 5800 | CK3: 11600 | CL3: 8000 | CM3: 16800 | CN3: 5800 | CO3: 11600 | CP3: 11600 | CQ3: 11600 | CR3: 11600 | CS3: 11600 | CT3: 11600 | CU3: 17500 | CV3: 11600 | CW3: 17500 | CX3: 11600 | CY3: 11600 | CZ3: 11600 | DA3: 0 | DB3: 0 | DC3: 0 | DD3: 24000 | DE3: 12000 | DF3: 12000 | DG3: 0 | DH3: 10000 | DI3: 10000 | DJ3: 10000 | DK3: 14000 | DL3: 14000 | DM3: 14000 | DN3: 14000 | DO3: 12000 | DP3: 17000 | DQ3: 17000 | DR3: 11600 | DS3: 17000 | DT3: 17000 | DU3: 11600 | DV3: 11600 | DW3: 17000 | DX3: 17000 | DY3: 11600 | DZ3: 17000 | EA3: 17000 | EB3: 11600 | EC3: 11600 | ED3: 17000 | EE3: 17000 | EF3: 11600 | EG3: 17000 | EH3: 17000 | EI3: 11600 | EJ3: 11600 | EK3: 11600 | EL3: 17000 | EM3: 11600 | EN3: 11600 | EO3: 17000 | EP3: 11600 | EQ3: 11600 | ER3: 11600 | ES3: 17000 | ET3: 11600
C4: 实际到货量 | E4: 1089 | I4: 4860 | J4: 4239 | K4: 4509 | L4: 2106 | M4: 0 | N4: 5508 | O4: 4536 | P4: 5724 | Q4: 8502 | R4: 7742 | S4: 1512 | T4: 1620 | U4: 5250 | V4: 2880 | W4: 5859 | X4: 5832 | Y4: 5850 | Z4: 10400 | AA4: 5184 | AB4: 6156 | AC4: 5544 | AD4: 11836 | AE4: 6112 | AF4: 11669 | AG4: 8986 | AH4: 10043 | AI4: 5744 | AJ4: 4860 | AK4: 11340 | AL4: 10280 | AM4: 5508 | AN4: 11268 | AO4: 11576 | AP4: 5832 | AQ4: 11988 | AR4: 5832 | AS4: 11664 | AT4: 6156 | AU4: 11016 | AV4: 12136 | AW4: 0 | AX4: 11664 | AY4: 11523 | AZ4: 11576 | BA4: 6068 | BB4: 11664 | BC4: 11576 | BD4: 0 | BE4: 11988 | BF4: 6392 | BG4: 11547 | BH4: 7407 | BI4: 17172 | BJ4: 0 | BK4: 17320 | BL4: 9956 | BM4: 0 | BN4: 11664 | BO4: 0 | BP4: =13662+5832 | BQ4: =7290+4338+6068 | BR4: 11016 | BS4: 13520 | BT4: 11900 | BU4: =5850+6480 | BV4: 16580 | BW4: 7364 | BX4: 10044 | BY4: =12872+5850 | BZ4: =11700+9720 | CG4: 11934 | CH4: 5850 | CI4: 5508 | CJ4: 0 | CK4: 5508 | CL4: =9396+5868 | CM4: =11789+5850 | CN4: =5850+972 | CO4: =13844 | CP4: 8649 | CQ4: =11700+9407 | CR4: =5945+1944 | CS4: 21979 | CT4: 0 | CU4: 12224 | CV4: 17408 | CW4: =5832+5832+11754 | CX4: =5850+11988 | CY4: 6156 | CZ4: 5420 | DA4: 0 | DB4: 0 | DC4: 0 | DD4: 0
L5: 枕芯气味问题，影响出货 | BK5: 台风停产一天 | BO5: 发往华南
B6: 内枕套到货计划 | C6: 预估到货量 | F6: 5500 | G6: 5500 | H6: 7000 | I6: 7000 | J6: 8400 | K6: 7000 | L6: 7000 | M6: 7000 | O6: 8000 | P6: 8500 | Q6: 8500 | R6: 10000 | S6: 10000 | T6: 12000 | U6: 13000 | V6: 13000 | W6: 15000 | X6: 15000 | Y6: 15000 | Z6: 15000 | AB6: 15000 | AC6: 15000 | AD6: 15000 | AE6: 15000 | AF6: 15000 | AG6: 18000 | AH6: 18000 | AI6: 18000 | AJ6: 18000 | AK6: 18000 | AL6: 20000 | AM6: 20000 | AN6: 20000 | AO6: 20000 | AP6: 20000 | AQ6: 20000 | AR6: 20000 | AS6: 20000 | AT6: 20000 | AU6: 20000 | AV6: 20000 | AW6: 20000 | AX6: 20000 | AY6: 20000 | AZ6: 20000 | BA6: 20000 | BB6: 20000 | BC6: 20000 | BD6: 20000 | BE6: 20000 | BF6: 20000 | BG6: 20000 | BH6: 20000 | BI6: 20000 | BJ6: 20000 | BK6: 20000 | BL6: 20000 | BM6: 20000 | BN6: 20000 | BO6: 20000 | BP6: 20000 | BQ6: 20000 | BR6: 20000 | BS6: 20000 | BT6: 20000 | BU6: 20000 | BV6: 20000 | BW6: 20000 | BX6: 20000 | BY6: 20000 | CH6: 华南 | CW6: 华南5832个
C7: 实际到货量 | F7: 5500 | G7: 5500 | H7: 6720 | I7: 4480 | J7: 8400 | K7: 0 | L7: 0 | M7: 0 | N7: 0 | O7: 8960 | P7: 8500 | Q7: 8400 | R7: 12040 | S7: 0 | T7: 11000 | U7: 0 | V7: 12040 | W7: 0 | X7: 12040 | Y7: 0 | Z7: 12040 | AA7: 0 | AB7: 12040 | AC7: 12040 | AD7: 12040 | AE7: 12040 | AF7: 12040 | AG7: 12040 | AH7: 12040 | AI7: 12040 | AJ7: 12040 | AK7: 12040 | AL7: 12040 | AM7: 12040 | AN7: 12040 | AO7: 12040 | AQ7: 12040 | AR7: 12040 | AS7: 12040 | AT7: 12040 | AU7: 12040 | AV7: 12040 | AX7: 12040 | AY7: 12040 | AZ7: 12040 | BA7: 12040 | BB7: 12040 | BC7: 12040
I8: 缺口25日到 | J8: 补缺口1400个 | K8: 生产正常，因为有库存，高裕通知停止 送货两天 | L8: 仍停止送货，生产5000每天 | M8: 仍停止送货，生产5000每天 | O8: 开始送货 | R8: 高裕要求2天送货一次 | T8: 高裕要求2天送货一次
B9: 外枕套到货计划 | C9: 预估到货量 | E9: 400 | F9: 600 | G9: 1500 | H9: 3800 | I9: 4400 | J9: 5200 | K9: 5500 | L9: 6800 | M9: 5000 | N9: 4400 | O9: 8200 | P9: 8700 | Q9: 5000 | R9: 4000 | S9: 4800 | T9: 5400 | U9: 5400 | V9: 6200 | W9: 7100 | X9: 7700 | Y9: 8400 | Z9: 9300 | AA9: 9500 | AB9: 7200 | AC9: 6000 | AD9: 10000 | AE9: 10000 | AF9: 10000 | AG9: 10000 | AH9: 10000 | AI9: 10000 | AJ9: 8000 | AK9: 10000 | AL9: 10000 | AM9: 10000 | AN9: 10000 | AO9: 10000 | AP9: 10000 | AQ9: 11000 | AR9: 11000 | AS9: 11000 | AT9: 11000 | AU9: 11000 | AV9: 0 | AW9: 11000 | AX9: 12000 | AY9: 12000 | AZ9: 12000 | BA9: 13000 | BB9: 13000 | BC9: 0 | BD9: 18000 | BE9: 14000 | BF9: 14000 | BG9: 14000 | BH9: 14000 | BI9: 14000 | BJ9: 0 | BK9: 14000 | BL9: 0 | BM9: 14000 | BN9: 14000 | BO9: 14000 | BP9: 14000 | BQ9: 0 | BR9: 14000 | BS9: 14000 | BT9: 14000 | BU9: 14000 | BV9: 14000 | BW9: 14000 | BX9: 0 | BY9: 14000
C10: 实际到货量 | E10: 400 | F10: 600 | G10: 1500 | H10: 3800 | I10: 4400 | J10: 5200 | K10: 5500 | L10: 6500 | M10: 4000 | N10: 3200 | O10: 8000 | P10: 4000 | Q10: 5000 | R10: 4000 | S10: 2000 | T10: 8200 | U10: 3000 | V10: 7000 | W10: 6200 | X10: 8000 | Y10: 8300 | Z10: 8900 | AA10: 8900 | AB10: 6400 | AC10: 9000 | AD10: 9300 | AE10: 9300 | AF10: 9500 | AG10: 9500 | AH10: 12000 | AI10: 3000 | AJ10: 11000 | AK10: 11000 | AL10: 10100 | AM10: 9000 | AN10: 11000 | AO10: 11000 | AP10: 5000 | AR10: 8500 | AS10: 11000 | AT10: 11000 | AV10: 10000 | AW10: 5000 | AX10: 10000 | AY10: 10000 | AZ10: 9000
R11: 刀口问题突出，不良率过高
Q12: 蓝色部分为东隆8.1更新新出货计划
AM18: 142921 | AN18: 85000
AM19: 159500 | AN19: 99000
AP20: =260000*0.85

Sheet 控温被PRO-S级品
B1: sku编码 | C1: 颜色 | D1: 尺寸 | E1: 45616 | F1: 45617 | G1: 45618 | H1: 45619 | I1: 45620 | J1: 45621 | K1: 45622 | L1: 45623 | M1: 45624 | N1: 45625 | O1: 45626 | P1: 45627 | Q1: 45628 | R1: 45629 | S1: 45630 | T1: 45631 | U1: 45632 | V1: 45633 | W1: 45634 | X1: 45635 | Y1: 45636 | Z1: 45637 | AA1: 45638 | AB1: 45639 | AC1: 45640 | AD1: 45641 | AE1: 45642 | AF1: 45643 | AG1: 45644 | AH1: 45645 | AI1: 45646 | AJ1: 45647 | AK1: 45648 | AL1: 45649 | AM1: 45650 | AN1: 45651 | AO1: 45652 | AP1: 45653 | AQ1: 45654 | AR1: 45655 | AS1: 45656 | AT1: 45657
A2: 四季被整被到货计划 | B2: 12800025601141516 | C2: 深空蓝 | D2: 150*200cm | E2: 0 | F2: 0 | G2: 0 | H2: 0 | I2: 0 | J2: 0 | K2: 0 | L2: 0 | M2: 0 | N2: 0 | O2: 0 | P2: 0 | Q2: 0 | R2: 0 | S2: 810 | T2: 0 | U2: 0 | V2: 0 | W2: 810 | X2: 0 | Y2: 0 | Z2: 0 | AA2: 810 | AB2: 0 | AC2: 0 | AD2: 0 | AE2: 702 | AF2: 0 | AG2: 0 | AH2: 0 | AI2: 936 | AJ2: 0 | AK2: 0 | AL2: 0 | AM2: 936 | AN2: 0 | AO2: 0 | AP2: 0 | AQ2: 1032 | AR2: 0 | AS2: 0 | AT2: 1230
B3: 12800025601141514 | D3: 200*230cm | E3: 0 | F3: 0 | G3: 0 | H3: 0 | I3: 0 | J3: 0 | K3: 0 | L3: 0 | M3: 0 | N3: 0 | O3: 0 | P3: 0 | Q3: 0 | R3: 0 | S3: 1440 | T3: 0 | U3: 0 | V3: 0 | W3: 1440 | X3: 0 | Y3: 0 | Z3: 0 | AA3: 1440 | AB3: 0 | AC3: 0 | AD3: 0 | AE3: 1200 | AF3: 0 | AG3: 0 | AH3: 0 | AI3: 1664 | AJ3: 0 | AK3: 0 | AL3: 0 | AM3: 1664 | AN3: 0 | AO3: 0 | AP3: 0 | AQ3: 1764 | AR3: 0 | AS3: 0 | AT3: 4058
B4: 12800025601141513 | D4: 220*240cm | E4: 0 | F4: 0 | G4: 0 | H4: 0 | I4: 0 | J4: 0 | K4: 0 | L4: 0 | M4: 0 | N4: 0 | O4: 0 | P4: 0 | Q4: 0 | R4: 0 | S4: 810 | T4: 0 | U4: 0 | V4: 0 | W4: 810 | X4: 0 | Y4: 0 | Z4: 0 | AA4: 810 | AB4: 0 | AC4: 0 | AD4: 0 | AE4: 702 | AF4: 0 | AG4: 0 | AH4: 0 | AI4: 936 | AJ4: 0 | AK4: 0 | AL4: 0 | AM4: 936 | AN4: 0 | AO4: 0 | AP4: 0 | AQ4: 1032 | AR4: 0 | AS4: 0 | AT4: 1430
B5: 12800025601141416 | C5: 黎明灰 | D5: 150*200cm | E5: 0 | F5: 0 | G5: 0 | H5: 0 | I5: 0 | J5: 0 | K5: 0 | L5: 0 | M5: 0 | N5: 0 | O5: 0 | P5: 0 | Q5: 0 | R5: 0 | S5: 408 | T5: 0 | U5: 0 | V5: 0 | W5: 408 | X5: 0 | Y5: 0 | Z5: 0 | AA5: 408 | AB5: 0 | AC5: 0 | AD5: 0 | AE5: 360 | AF5: 0 | AG5: 0 | AH5: 0 | AI5: 480 | AJ5: 0 | AK5: 0 | AL5: 0 | AM5: 480 | AN5: 0 | AO5: 0 | AP5: 0 | AQ5: 576 | AR5: 0 | AS5: 0 | AT5: 1871
B6: 12800025601141414 | D6: 200*230cm | E6: 0 | F6: 0 | G6: 0 | H6: 0 | I6: 0 | J6: 0 | K6: 0 | L6: 0 | M6: 0 | N6: 0 | O6: 0 | P6: 0 | Q6: 0 | R6: 0 | S6: 628 | T6: 0 | U6: 0 | V6: 0 | W6: 628 | X6: 0 | Y6: 0 | Z6: 0 | AA6: 628 | AB6: 0 | AC6: 0 | AD6: 0 | AE6: 552 | AF6: 0 | AG6: 0 | AH6: 0 | AI6: 736 | AJ6: 0 | AK6: 0 | AL6: 0 | AM6: 736 | AN6: 0 | AO6: 0 | AP6: 0 | AQ6: 765 | AR6: 0 | AS6: 0 | AT6: 1000
B7: 12800025601141413 | D7: 220*240cm | E7: 0 | F7: 0 | G7: 0 | H7: 0 | I7: 0 | J7: 0 | K7: 0 | L7: 0 | M7: 0 | N7: 0 | O7: 0 | P7: 0 | Q7: 0 | R7: 0 | S7: 408 | T7: 0 | U7: 0 | V7: 0 | W7: 408 | X7: 0 | Y7: 0 | Z7: 0 | AA7: 408 | AB7: 0 | AC7: 0 | AD7: 0 | AE7: 360 | AF7: 0 | AG7: 0 | AH7: 0 | AI7: 480 | AJ7: 0 | AK7: 0 | AL7: 0 | AM7: 480 | AN7: 0 | AO7: 0 | AP7: 0 | AQ7: 0 | AR7: 0 | AS7: 0 | AT7: 500
B8: 12800025601141316 | C8: 朦胧黄 | D8: 150*200cm | E8: 0 | F8: 0 | G8: 0 | H8: 0 | I8: 0 | J8: 0 | K8: 0 | L8: 0 | M8: 0 | N8: 0 | O8: 0 | P8: 0 | Q8: 0 | R8: 0 | S8: 0 | T8: 0 | U8: 0 | V8: 0 | W8: 0 | X8: 0 | Y8: 0 | Z8: 0 | AA8: 0 | AB8: 0 | AC8: 0 | AD8: 0 | AE8: 0 | AF8: 0 | AG8: 0 | AH8: 0 | AI8: 0 | AJ8: 0 | AK8: 0 | AL8: 0 | AM8: 0 | AN8: 0 | AO8: 0 | AP8: 0 | AQ8: 0 | AR8: 0 | AS8: 0 | AT8: 204
B9: 12800025601141314 | D9: 200*230cm | E9: 0 | F9: 0 | G9: 0 | H9: 0 | I9: 0 | J9: 0 | K9: 0 | L9: 0 | M9: 0 | N9: 0 | O9: 0 | P9: 0 | Q9: 0 | R9: 0 | S9: 0 | T9: 0 | U9: 0 | V9: 0 | W9: 0 | X9: 0 | Y9: 0 | Z9: 0 | AA9: 0 | AB9: 0 | AC9: 0 | AD9: 0 | AE9: 0 | AF9: 0 | AG9: 0 | AH9: 0 | AI9: 0 | AJ9: 0 | AK9: 0 | AL9: 0 | AM9: 0 | AN9: 0 | AO9: 0 | AP9: 0 | AQ9: 0 | AR9: 0 | AS9: 0 | AT9: 300
B10: 12800025601141313 | D10: 220*240cm | E10: 0 | F10: 0 | G10: 0 | H10: 0 | I10: 0 | J10: 0 | K10: 0 | L10: 0 | M10: 0 | N10: 0 | O10: 0 | P10: 0 | Q10: 0 | R10: 0 | S10: 0 | T10: 0 | U10: 0 | V10: 0 | W10: 0 | X10: 0 | Y10: 0 | Z10: 0 | AA10: 0 | AB10: 0 | AC10: 0 | AD10: 0 | AE10: 0 | AF10: 0 | AG10: 0 | AH10: 0 | AI10: 0 | AJ10: 0 | AK10: 0 | AL10: 0 | AM10: 0 | AN10: 0 | AO10: 0 | AP10: 0 | AQ10: 0 | AR10: 0 | AS10: 0 | AT10: 200
B11: 计划到货量 | E11: 0 | F11: 0 | G11: 0 | H11: 0 | I11: 0 | J11: 0 | K11: 0 | L11: 0 | M11: 0 | N11: 0 | O11: 0 | P11: 0 | Q11: 0 | R11: 0 | S11: 4504 | T11: 0 | U11: 0 | V11: 0 | W11: 4504 | X11: 0 | Y11: 0 | Z11: 0 | AA11: 4504 | AB11: 0 | AC11: 0 | AD11: 0 | AE11: 3876 | AF11: 0 | AG11: 0 | AH11: 0 | AI11: 5232 | AJ11: 0 | AK11: 0 | AL11: 0 | AM11: 5232 | AN11: 0 | AO11: 0 | AP11: 0 | AQ11: 5169 | AR11: 0 | AS11: 0 | AT11: 10793

Sheet 控温被系列交付汇总
J1: 预计 | M1: 夏凉被1月试产 | N1: 夏凉被主要生产时间 | O1: 和夏凉被冲突
D2: 已接需求 | E2: 已下单 | F2: 待下单 | G2: 其他备料 | H2: 在途 | I2: 截止930交货 | J2: 10月 | K2: 11月 | L2: 12月 | M2: 1月 | N2: 2月 | O2: 3月 | P2: 产能爬坡 | U2: 纽培 | W2: 已接需求 | X2: 已下单 | Y2: 待下单 | Z2: 其他备料 | AA2: 在途 | AB2: 日需 | AC2: 截止1028交货 | AD2: 10月 | AE2: 11月 | AF2: 12月 | AG2: 1月 | AH2: 2月 | AI2: 3月 | AJ2: 产能爬坡 | AK2: 需求日期
B3: 整被-四季被 | C3: 万青 | D3: =SUM(E3:G5) | E3: =#REF! | H3: =#REF! | I3: =#REF!+#REF!+#REF!+#REF! | J3: 30372 | K3: 54000 | L3: 10800 | M3: =E3-I3-J3-K3-L3 | P3: 1400-1800 | R3: =L3/18 | U3: 整被-四季被 | V3: 万青 | W3: =X4+X5+Y5+X3 | X3: 25000 | AA3: =W3-AC4 | AJ3: 2W在库待发。1-2W待全检
C4: 优绵 | E4: =#REF! | H4: =#REF! | I4: =#REF!+#REF!+#REF! | J4: 13052 | K4: / | L4: 25000 | M4: 20000 | O4: =E4-I4-J4-L4-M4 | P4: / | V4: 优绵 | X4: 116119 | AC4: =29500+39384 | AK4: 11月中旬
C5: 迦南 | E5: 600 | F5: =28000-E5 | K5: 8000 | L5: =15000 | M5: 5000 | V5: 迦南 | X5: 600 | Y5: =28000-X5
B6: 整被-冬被 | C6: 万青 | D6: 183070 | F6: =L6 | H6: =D6-8000 | I6: 0 | L6: =8600+5400 | P6: 11/5 500 11/12 750 11/19 1000 11/26 1000 12/3 1000 | U6: 整被-冬被 | V6: 万青 | W6: 183070 | X6: 161070 | Z6: 2W | AA6: =X6-AC7-AC8 | AB6: 500 | AE6: 3700 | AF6: =14000-AE6 | AJ6: 目前2600-2800，11/5：3500，11/10到4000。（合计10.1W） | AK6: 45611
C7: 优绵 | E7: =#REF! | F7: 9000 | J7: 30000 | K7: 48000 | L7: =2000+9000 | P7: 10/18 1200 10/25 1500 11/5 1800 11/25 2000 | Q7: 12月下半月会给别的客户，90%变80%；1月变50-60% | R7: 60w的夏被，四季被只考虑到3月份，每天5-8百；7月开始又进入四季被 | V7: 优绵 | AB7: 2800 | AC7: 37850 | AD7: =AC7 | AE7: =E7-AD7
C8: 东隆 | E8: 58070 | F8: =22000 | J8: 14793 | K8: =30070+10000 | L8: 22000 | P8: 11月1w需要芜湖cover | V8: 东隆 | AB8: 1500 | AC8: 18886 | AD8: 20000 | AE8: =1500*30 | AF8: 17000
B9: 排湿层单层 | C9: 万青 | D9: =SUM(E9:E11)+SUM(G9:G12) | E9: ='控温被PRO单层出货计划&生产数据'!E19 | H9: =D9 | L9: 27500 | U9: 排湿层单层 | V9: 万青 | W9: =E10+E9+Z9 | X9: =W9-Z9 | Z9: 10000 | AA9: =W9-AC9 | AB9: 1200 | AC9: 12871 | AE9: =AB9*28 | AF9: =W9-AC9-AE9 | AJ9: 目前1500，可以提到2200（通知后3天左右出产能） | AK9: 11月中旬
C10: 优绵 | E10: ='控温被PRO单层出货计划&生产数据'!E29 | G10: 10000 | K10: 2000 | L10: =25500-11500 | N10: =E10-K10-L10 | O10: 10000 | V10: 优绵
C11: 东隆 | V11: 东隆
B12: 蓄热层-四季 | C12: 万青 | D12: =SUM(E12) | E12: 14000 | H12: =D12 | M12: =H12-L12 | U12: 蓄热层-四季 | V12: 万青 | W12: 14000 | AF12: =14000
B13: 蓄热层-冬季 | C13: 优绵 | D13: =E13+E14 | E13: 16000 | K13: 2000 | L13: 14000 | U13: 蓄热层-冬季 | V13: 优绵 | W13: 26000 | X13: 16000 | AA13: =W13-AC13 | AB13: 1000 | AD13: 2150 | AE13: =AB13*28 | AF13: 2500
C14: 东隆 | E14: 10000 | L14: 10000 | V14: 东隆 | X14: 10000 | AK14: 包装，签样未签
D15: =SUM(D3:D14) | E15: =SUM(E3:E14) | F15: =SUM(F3:F14) | G15: =SUM(G3:G14) | H15: =SUM(H3:H14) | I15: =SUM(I3:I14) | J15: =SUM(J3:J14) | K15: =SUM(K3:K14) | ... O15: =SUM(O3:O14) | W15: =SUM(W3:W14) | X15: =SUM(X3:X14) | Y15: =SUM(Y3:Y14) | Z15: =SUM(Z3:Z14) | AA15: 10000 | AC15: =SUM(AC3:AC14) | AD15: =SUM(AD3:AD14) | AE15: =SUM(AE3:AE14) | AF15: =SUM(AF3:AF13) | AG15: =SUM(AG3:AG14) | AH15: =SUM(AH3:AH14) | AI15: =SUM(AI3:AI14)
J17: 10月 | K17: 11月 | L17: 12月 | M17: 1月 | N17: 2月 | O17: 3月
I18: 万青 | J18: =SUMIF($C$3:$C$8,$I18,J$3:J$8)+SUMIF($C$9:$C$14,$I18,J$9:J$14)/2 | K18: =SUMIF($C$3:$C$8,$I18,K$3:K$8)+SUMIF($C$9:$C$14,$I18,K$9:K$14)/2 | L18: =SUMIF($C$3:$C$8,$I18,L$3:L$8)+SUMIF($C$9:$C$14,$I18,L$9:L$14)/2 | M18: =SUMIF($C$3:$C$8,$I18,M$3:M$8)+SUMIF($C$9:$C$14,$I18,M$9:M$14)/2 | N18: =SUMIF($C$3:$C$8,$I18,N$3:N$8)+SUMIF($C$9:$C$14,$I18,N$9:N$14)/2 | O18: =SUMIF($C$3:$C$8,$I18,O$3:O$8)+SUMIF($C$9:$C$14,$I18,O$9:O$14)/2 | W18: 10月 | X18: 11月 | Y18: 12月 | Z18: 1月 | AA18: 2月 | AB18: 3月 | AC18: 需求总数 | AJ18: =2800*4
I19: 优绵 | J19: =SUMIF($C$3:$C$8,$I19,J$3:J$8)+SUMIF($C$9:$C$14,$I19,J$9:J$14)/2 | K19: =SUMIF($C$3:$C$8,$I19,K$3:K$8)+SUMIF($C$9:$C$14,$I19,K$9:K$14)/2 | L19: =SUMIF($C$3:$C$8,$I19,L$3:L$8)+SUMIF($C$9:$C$14,$I19,L$9:L$14)/2 | M19: =SUMIF($C$3:$C$8,$I19,M$3:M$8)+SUMIF($C$9:$C$14,$I19,M$9:M$14)/2 | N19: =SUMIF($C$3:$C$8,$I19,N$3:N$8)+SUMIF($C$9:$C$14,$I19,N$9:N$14)/2 | O19: =SUMIF($C$3:$C$8,$I19,O$3:O$8)+SUMIF($C$9:$C$14,$I19,O$9:O$14)/2 | V19: 四季被-整被 | W19: =SUM(AD3:AD5) | X19: =SUM(AE3:AE5) | Y19: =SUM(AF3:AF5) | Z19: =SUM(AG3:AG5) | AA19: =SUM(AH3:AH5) | AB19: =SUM(AI3:AI5) | AC19: =SUM(W19:AB19) | AJ19: =3500*4
I20: 东隆 | J20: =SUMIF($C$3:$C$8,$I20,J$3:J$8)+SUMIF($C$9:$C$14,$I20,J$9:J$14)/2 | K20: =SUMIF($C$3:$C$8,$I20,K$3:K$8)+SUMIF($C$9:$C$14,$I20,K$9:K$14)/2 | L20: =SUMIF($C$3:$C$8,$I20,L$3:L$8)+SUMIF($C$9:$C$14,$I20,L$9:L$14)/2 | M20: =SUMIF($C$3:$C$8,$I20,M$3:M$8)+SUMIF($C$9:$C$14,$I20,M$9:M$14)/2 | N20: =SUMIF($C$3:$C$8,$I20,N$3:N$8)+SUMIF($C$9:$C$14,$I20,N$9:N$14)/2 | O20: =SUMIF($C$3:$C$8,$I20,O$3:O$8)+SUMIF($C$9:$C$14,$I20,O$9:O$14)/2 | V20: 冬被-整被 | W20: =SUM(AC6:AC8) | X20: =SUM(AD6:AD8) | Y20: =SUM(AE6:AE8) | Z20: =SUM(AF6:AF8) | AA20: =SUM(AG6:AG8) | AB20: =SUM(AH6:AH8) | AC20: =SUM(W20:AB20) | AI20: =4000*4 | AJ20: =4000*19
I21: 迦南 | J21: =SUMIF($C$3:$C$8,$I21,J$3:J$8)+SUMIF($C$9:$C$14,$I21,J$9:J$14)/2 | K21: =SUMIF($C$3:$C$8,$I21,K$3:K$8)+SUMIF($C$9:$C$14,$I21,K$9:K$14)/2 | L21: =SUMIF($C$3:$C$8,$I21,L$3:L$8)+SUMIF($C$9:$C$14,$I21,L$9:L$14)/2 | M21: =SUMIF($C$3:$C$8,$I21,M$3:M$8)+SUMIF($C$9:$C$14,$I21,M$9:M$14)/2 | N21: =SUMIF($C$3:$C$8,$I21,N$3:N$8)+SUMIF($C$9:$C$14,$I21,N$9:N$14)/2 | O21: =SUMIF($C$3:$C$8,$I21,O$3:O$8)+SUMIF($C$9:$C$14,$I21,O$9:O$14)/2 | V21: 排湿层 | W21: =SUM(AD9:AD11) | X21: =SUM(AE9:AE11) | Y21: =SUM(AF9:AF11) | Z21: =SUM(AG9:AG11) | AA21: =SUM(AH9:AH11) | AB21: =SUM(AI9:AI11) | AC21: =SUM(W21:AB21) | AI21: =AI20+AJ18+AJ19
I22: 合计 | J22: =SUM(J18:J21) | K22: =SUM(K18:K21) | L22: =SUM(L18:L21) | M22: =SUM(M18:M21) | N22: =SUM(N18:N21) | O22: =SUM(O18:O21) | V22: 四季被-单层 | W22: =SUM(AD12) | X22: =SUM(AE12) | Y22: =SUM(AF12) | Z22: =SUM(AG12) | AA22: =SUM(AH12) | AB22: =SUM(AI12) | AC22: =SUM(W22:AB22)
V23: 冬被-单层 | W23: =SUM(AD13:AD14) | X23: =SUM(AE13:AE14) | Y23: =SUM(AF13) | Z23: =SUM(AG13:AG14) | AA23: =SUM(AH13:AH14) | AB23: =SUM(AI13:AI14) | AC23: =SUM(W23:AB23)
W24: =SUM(W19:W23) | X24: =SUM(X19:X23) | Y24: =SUM(Y19:Y23) | Z24: =SUM(Z19:Z23) | AA24: =SUM(AA19:AA23) | AB24: =SUM(AB19:AB23) | AC24: =SUM(AC19:AC23)
I25: 产能max | J25: 10月 | K25: 11月 | L25: 12月 | M25: 1月
I26: 万青 | J26: 30802 | K26: =K18 | L26: 58000 | M26: =L26/3
I27: 优绵 | J27: =J19 | K27: =K19 | L27: =1800*28 | M27: =L27/3
I28: 东隆 | J28: =J20 | K28: 30000 | L28: 30000 | M28: =L28/3
I29: 迦南 | J29: 0 | K29: 10000 | L29: 15000 | M29: =L29/3
E31: 10月销售预测 | F31: 11月销售预测 | G31: 12月销售预测 | H31: 1月销售预测 | I31: 2月销售预测 | K31: 10月 | L31: 11月 | M31: 12月 | N31: 1月 | O31: 2月 | P31: 3月
D32: 四季被-整被 | E32: 35587 | F32: 44138 | G32: 41358 | H32: 36823 | I32: =H32*0.8 | J32: 四季被-整被 | K32: =SUM(J3:J5) | L32: =SUM(K3:K5) | M32: =SUM(L3:L5) | N32: =SUM(M3:M5) | O32: =SUM(N3:N5) | P32: =SUM(O3:O5)
D33: 冬被-整被 | E33: 33546 | F33: 51075 | G33: 46265 | H33: 36054 | I33: =H33*0.5 | J33: 冬被-整被 | K33: =SUM(J6:J8) | L33: =SUM(K6:K8) | M33: =SUM(L6:L8) | N33: =SUM(M6:M8) | O33: =SUM(N6:N8) | P33: =SUM(O6:O8)
J34: 排湿层 | K34: =SUM(J9:J11) | L34: =SUM(K9:K11) | M34: =SUM(L9:L11) | N34: =SUM(M9:M11) | O34: =SUM(N9:N11) | P34: =SUM(O9:O11)
J35: 四季被-单层 | K35: =SUM(J12) | L35: =SUM(K12) | M35: =SUM(L12) | N35: =SUM(M12) | O35: =SUM(N12) | P35: =SUM(O12)
J36: 冬被-单层 | K36: =SUM(J13:J14) | L36: =SUM(K13:K14) | M36: =SUM(L13:L14) | N36: =SUM(M13:M14) | O36: =SUM(N13:N14) | P36: =SUM(O13:O14)
K37: =SUM(K32:K36) | L37: =SUM(L32:L36) | M37: =SUM(M32:M36) | N37: =SUM(N32:N36) | O37: =SUM(O32:O36) | P37: =SUM(P32:P36)
B40: 优先冬被，四季被持续交货 | D40: 已接需求 | E40: 已下单 | F40: 待下单 | G40: 其他备料 | H40: 在途 | I40: 截止930交货 | J40: 10月 | K40: 11月 | L40: 12月 | M40: 1月 | N40: 2月 | O40: 3月 | P40: 产能爬坡
B41: 整被-四季被 | C41: 万青 | D41: =SUM(E41:G43) | E41: 152145 | F41: =28000-F43 | H41: 94907 | I41: 41500 | J41: 30372 | K41: 54000 | M41: 15000 | N41: =L3-M41 | P41: 1400-1800
C42: 优绵 | E42: 116119 | H42: 55424 | I42: 47643 | J42: 13052 | K42: / | L42: =H42-M42-N42 | M42: 15000 | N42: 5000 | P42: /
C43: 迦南 | F43: 28000 | K43: 8000 | L43: =15000 | M43: 5000 | R43: =L42
B44: 整被-冬被 | C44: 万青 | D44: =SUM(E44:E46)+SUM(G44)+SUM(F44:F46) | F44: 13000 | G44: 需要额外1.3w产能 | H44: 175070 | I44: 175070 | L44: 13000 | P44: 11/5 500 11/12 750 11/19 1000 11/26 1000 12/3 1000
...

Sheet 控温被PRO单层出货计划&生产数据
A1: 名称 | B1: SKU | C1: 颜色 | D1: 尺寸 | E1: 订单总数 | F1: 已入库 | G1: 未入库 | H1: 45627 | I1: 45628 | J1: 45629 | K1: 45630 | L1: 45631 | M1: 45632 | N1: 45633 | O1: 45634 | P1: 45635 | Q1: 45636 | R1: 45637 | S1: 45638 | T1: 45639 | U1: 45640 | V1: 45641 | W1: 45642 | X1: 45643 | Y1: 45644 | Z1: 45645 | AA1: 45646 | AB1: 45647 | AC1: 45648 | AD1: 45649 | AE1: 45650 | AF1: 45651 | AG1: 45652 | AH1: 45653 | AI1: 45654 | AJ1: 45655 | AK1: 45656 | AL1: 45657
A2: 亚朵星球 深睡控温被PRO 排湿层 | B2: 010020103030019-001 | C2: 淡蓝【搭配深空蓝】 | D2: 150*200cm | E2: =E13+E23 | H2: =M13+I23 | I2: =N13+J23 | J2: =O13+K23 | K2: =P13+L23 | L2: =Q13+M23 | M2: =R13+N23 | N2: =S13+O23 | O2: =T13+P23 | ... AL2: =AQ13+AM23
B3: 010020103030019-002 | D3: 200*230cm | E3: =E14+E24 | H3: =M14+I24 | I3: =N14+J24 | J3: =O14+K24 | K3: =P14+L24 | L3: =Q14+M24 | M3: =R14+N24 | N3: =S14+O24 | O3: =T14+P24 | ... AL3: =AQ14+AM24
B4: 010020103030019-003 | D4: 220*240cm | E4: =E15+E25 | H4: =M15+I25 | I4: =N15+J25 | J4: =O15+K25 | K4: =P15+L25 | L4: =Q15+M25 | M4: =R15+N25 | N4: =S15+O25 | O4: =T15+P25 | ... AL4: =AQ15+AM25
B5: 010020103030019-004 | C5: 浅米【搭配黎明灰 &朦胧黄】 | D5: 150*200cm | E5: =E16+E26 | H5: =M16+I26 | I5: =N16+J26 | J5: =O16+K26 | K5: =P16+L26 | L5: =Q16+M26 | M5: =R16+N26 | N5: =S16+O26 | O5: =T16+P26 | ... AL5: =AQ16+AM26
B6: 010020103030019-005 | D6: 200*230cm | E6: =E17+E27 | H6: =M17+I27 | I6: =N17+J27 | J6: =O17+K27 | K6: =P17+L27 | L6: =Q17+M27 | M6: =R17+N27 | N6: =S17+O27 | O6: =T17+P27 | ... AL6: =AQ17+AM27
B7: 010020103030019-006 | D7: 220*240cm | E7: =E18+E28 | H7: =M18+I28 | I7: =N18+J28 | J7: =O18+K28 | K7: =P18+L28 | L7: =Q18+M28 | M7: =R18+N28 | N7: =S18+O28 | O7: =T18+P28 | ... AL7: =AQ18+AM28
B8: 计划到货 | E8: =SUM(E2:E7) | H8: =SUM(H2:H7) | I8: =SUM(I2:I7) | J8: =SUM(J2:J7) | K8: =SUM(K2:K7) | L8: =SUM(L2:L7) | M8: =SUM(M2:M7) | N8: =SUM(N2:N7) | O8: =SUM(O2:O7) | ... AL8: =SUM(AL2:AL7)
L9: 华南仓
A11: 名称 | B11: SKU | C11: 颜色 | D11: 尺寸 | E11: 万青 | F11: 已入库 | G11: 未入库
E12: 首单 | H12: 45627 | I12: 45628 | J12: 45629 | K12: 45630 | L12: 45631 | M12: 45632 | N12: 45633 | O12: 45634 | P12: 45635 | Q12: 45636 | R12: 45637 | S12: 45638 | T12: 45639 | U12: 45640 | V12: 45641 | W12: 45642 | X12: 45643 | Y12: 45644 | Z12: 45645 | AA12: 45646 | AB12: 45647 | AC12: 45648 | AD12: 45649 | AE12: 45650 | AF12: 45651 | AG12: 45652 | AH12: 45653 | AI12: 45654 | AJ12: 45655 | AK12: 45656 | AL12: 45657
A13: 亚朵星球 深睡控温被PRO 排湿层 | B13: 010020103030019-001 | C13: 淡蓝 【搭配深空蓝】 | D13: 150*200cm | E13: 2475 | G13: =E13-F13 | L13: 450 | Q13: 450 | V13: 450 | AA13: 450 | AF13: 450 | AL13: 225
B14: 010020103030019-002 | D14: 200*230cm | E14: 6850 | G14: =E14-F14 | L14: 1300 | Q14: 1300 | V14: 1200 | AA14: 1200 | AF14: 1250 | AL14: 600
B15: 010020103030019-003 | D15: 220*240cm | E15: 3075 | G15: =E15-F15 | L15: 600 | Q15: 600 | V15: 450 | AA15: 550 | AF15: 550 | AL15: 325
B16: 010020103030019-004 | C16: 浅米 【搭配黎明灰 &朦胧黄】 | D16: 150*200cm | E16: 3000 | G16: =E16-F16 | L16: 500 | Q16: 500 | V16: 650 | AA16: 550 | AF16: 550 | AL16: 250
B17: 010020103030019-005 | D17: 200*230cm | E17: 8325 | G17: =E17-F17 | L17: 1500 | Q17: 1500 | V17: 1500 | AA17: 1550 | AF17: 1525 | AL17: 750
B18: 010020103030019-006 | D18: 220*240cm | E18: 3775 | G18: =E18-F18 | L18: 650 | Q18: 650 | V18: 750 | AA18: 700 | AF18: 675 | AL18: 350
C19: 合计 | E19: 27500 | G19: =SUM(G13:G18) | L19: =SUM(L13:L18) | M19: =SUM(M13:M18) | N19: =SUM(N13:N18) | O19: =SUM(O13:O18) | P19: =SUM(P13:P18) | Q19: =SUM(Q13:Q18) | R19: =SUM(R13:R18) | S19: =SUM(S13:S18) | ... AL19: =SUM(AL13:AL18)
A21: 名称 | B21: SKU | C21: 颜色 | D21: 尺寸 | E21: 优绵 | F21: 已入库 | G21: 未入库
E22: 首单 | H22: 45627 | I22: 45628 | J22: 45629 | K22: 45630 | L22: 45631 | M22: 45632 | N22: 45633 | O22: 45634 | P22: 45635 | Q22: 45636 | R22: 45637 | S22: 45638 | T22: 45639 | U22: 45640 | V22: 45641 | W22: 45642 | X22: 45643 | Y22: 45644 | Z22: 45645 | AA22: 45646 | AB22: 45647 | AC22: 45648 | AD22: 45649 | AE22: 45650 | AF22: 45651 | AG22: 45652 | AH22: 45653 | AI22: 45654 | AJ22: 45655 | AK22: 45656 | AL22: 45657
A23: 亚朵星球 深睡控温被PRO 排湿层 | B23: 010020103030019-001 | C23: 淡蓝 【搭配深空蓝】 | D23: 150*200cm | E23: 2475 | L23: 1000 | O23: 852
B24: 010020103030019-002 | D24: 200*230cm | E24: 6850 | L24: 1500 | O24: 1000 | R24: 1826
B25: 010020103030019-003 | D25: 220*240cm | E25: 3075 | L25: 500 | O25: 1000 | R25: 922
B26: 010020103030019-004 | C26: 浅米 【搭配黎明灰 &朦胧黄】 | D26: 150*200cm | E26: 3000 | L26: 200 | O26: 500 | R26: 468
B27: 010020103030019-005 | D27: 200*230cm | E27: 8325 | L27: 1000 | O27: 1290 | R27: 423
B28: 010020103030019-006 | D28: 220*240cm | E28: 3775 | L28: 200 | O28: 700 | R28: 619
C29: 合计 | E29: 27500 | L29: =SUM(L23:L28) | M29: =SUM(M23:M28) | N29: =SUM(N23:N28) | O29: =SUM(O23:O28) | P29: =SUM(P23:P28) | Q29: =SUM(Q23:Q28) | R29: =SUM(R23:R28)
A37: 名称 | B37: 颜色 | C37: 尺寸 | D37: 下单占比 | E37: 优绵 | F37: 首单
F38: 合计 | G38: 45606 | H38: 45631 | I38: 45634 | J38: 45637
A39: 深睡控温冬被PRO-蓄热层 | B39: 远山蓝 | C39: 150*200cm | D39: 0.1364 | E39: 2182.4 | F39: 2182.4 | G39: 330 | H39: 1000 | I39: 852
C40: 200*230cm | D40: 0.31 | E40: 4960 | F40: 4960 | G40: 634 | H40: 1500 | I40: 1000 | J40: 1826
C41: 220*240cm | D41: 0.1736 | E41: 2777.6 | F41: 2777.6 | G41: 356 | H41: 500 | I41: 1000 | J41: 922
B42: 雾凇粉 | C42: 150*200cm | D42: 0.0616 | E42: 985.6 | F42: 985.6 | G42: 130 | H42: 200 | I42: 400 | J42: 256
C43: 200*230cm | D43: 0.14 | E43: 2240 | F43: 2240 | G43: 250 | H43: 1000 | I43: 990
C44: 220*240cm | D44: 0.0784 | E44: 1254.4 | F44: 1254.4 | G44: 140 | H44: 200 | I44: 500 | J44: 414
B45: 云朵白 | C45: 150*200cm | D45: 0.022 | E45: 352 | F45: 352 | G45: 40 | I45: 100 | J45: 212
C46: 200*230cm | D46: 0.05 | E46: 800 | F46: 800 | G46: 77 | I46: 300 | J46: 423
C47: 220*240cm | D47: 0.028 | E47: 448 | F47: 448 | G47: 43 | I47: 200 | J47: 205
B48: 合计 | D48: 1 | E48: 16000 | F48: 16000 | G48: 6153.8462 | H48: 6153.8462 | I48: 3692.3077 | J48: 3693.3077
A50: 名称 | B50: 颜色 | C50: 尺寸 | D50: 下单占比 | E50: 东隆 | F50: 首单
...

Sheet 迁移数据
A1: 优绵整被 | B1: 1.更新每日成品数量 2.第3行请注明对应生产批次（例如7/22-7/27生产7/30到货，那就填写7/30批次） | C1: 0 | D1: 0 | E1: 0 | F1: 0 | G1: 0 | H1: 0 | I1: 0 | J1: 0 | K1: 0 | L1: 0 | M1: 0 | N1: 0 | O1: 0 | P1: 0 | Q1: 0 | R1: 0 | S1: 0 | T1: 0 | U1: 0 | V1: 0 | W1: 0 | X1: 0 | Y1: 0 | Z1: 0 | AA1: 0 | AB1: 0 | AC1: 0 | AD1: 0 | AE1: 0 | AF1: 0 | AG1: 0 | AH1: 0 | AI1: 0 | AJ1: 0 | AK1: 0 | AL1: 0 | AM1: 0 | AN1: 0 | AO1: 0 | AP1: 0 | AQ1: 0 | AR1: 0 | AS1: 0 | AT1: 0 | AU1: 0 | AV1: 0 | AW1: 0 | AX1: 0 | AY1: 0 | AZ1: 0 | BA1: 0 | BB1: 0 | BC1: 0 | BD1: 0 | BE1: 0 | BF1: 0 | BG1: 0 | BH1: 0 | BI1: 0 | BJ1: 0 | BK1: 0 | BL1: 0 | BM1: 0 | BN1: 0 | BO1: 0 | BP1: 0 | BQ1: 0 | BR1: 0 | BS1: 0 | BT1: 0 | BU1: 0 | BV1: 0 | BW1: 0 | BX1: 0 | BY1: 0 | BZ1: 0 | CA1: 0 | CB1: 0 | CC1: 0 | CD1: 0 | CE1: 0 | CF1: 0 | CG1: 0 | CH1: 0 | CI1: 0 | CJ1: 0 | CK1: 0 | CL1: 0 | CM1: 0 | CN1: 0 | CO1: 0 | CP1: 0 | CQ1: 0 | CR1: 0 | CS1: 0 | CT1: 0 | CU1: 0 | CV1: 0 | CW1: 0 | CX1: 0 | CY1: 0 | CZ1: 0 | DA1: 0 | DB1: 0 | DC1: 0 | DD1: 0 | DE1: 0 | DF1: 0 | DG1: 0 | DH1: 0 | DI1: 0 | DJ1: 0 | DK1: 0 | DL1: 0 | DM1: 0 | DN1: 0 | DO1: 0 | DP1: 0 | DQ1: 0 | DR1: 0 | DS1: 0 | DT1: 0 | DU1: 0 | DV1: 0 | DW1: 0 | DX1: 0 | DY1: 0 | DZ1: 0 | EA1: 0 | EB1: 0 | EC1: 0 | ED1: 0 | EE1: 0 | EF1: 0 | EG1: 0 | EH1: 0 | EI1: 0 | EJ1: 0 | EK1: 0 | EL1: 0 | EM1: 0 | EN1: 0 | EO1: 0 | EP1: 0 | EQ1: 0 | ER1: 0 | ES1: 0 | ET1: 0 | EU1: 0 | EV1: 0 | EW1: 0 | EX1: 0 | EY1: 0 | EZ1: 0 | FA1: 0 | FB1: 0 | FC1: 0 | FD1: 0 | FE1: 0 | FF1: 0 | FG1: 0 | FH1: 0 | FI1: 0 | FJ1: 0 | FK1: 0 | FL1: 0 | FM1: 0 | FN1: 0 | FO1: 0 | FP1: 0 | FQ1: 0 | FR1: 0 | FS1: 0 | FT1: 0 | FU1: 0 | FV1: 0 | FW1: 0 | FX1: 0 | FY1: 0 | FZ1: 0 | GA1: 0 | GB1: 0 | GC1: 0 | GD1: 0 | GE1: 0 | GF1: 0 | GG1: 0 | GH1: 0 | GI1: 0 | GJ1: 0 | GK1: 0 | GL1: 0 | GM1: 0 | GN1: 0 | GO1: 0 | GP1: 0 | GQ1: 0 | GR1: 0 | GS1: 0 | GT1: 0 | GU1: 0 | GV1: 0 | GW1: 0 | GX1: 0 | GY1: 0 | GZ1: 0 | HA1: 0 | HB1: 0 | HC1: 0 | HD1: 0 | HE1: 0 | HF1: 0 | HG1: 0 | HH1: 0 | HI1: 0 | HJ1: 0 | HK1: 0 | HL1: 0 | HM1: 0 | HN1: 0 | HO1: 0 | HP1: 0 | HQ1: 0 | HR1: 0 | HS1: 0 | HT1: 0 | HU1: 0 | HV1: 0 | HW1: 0 | HX1: 0 | HY1: 0 | HZ1: 0 | IA1: 0 | IB1: 0 | IC1: 0 | ID1: 0 | IE1: 0 | IF1: 0 | IG1: 0 | IH1: 0 | II1: 0 | IJ1: 0 | IK1: 0 | IL1: 0 | IM1: 0 | IN1: 0 | IO1: 0 | IP1: 0 | IQ1: 0 | IR1: 0 | IS1: 0 | IT1: 0 | IU1: 0 | IV1: 0 | IW1: 0 | IX1: 0 | IY1: 0 | IZ1: 0 | JA1: 0 | JB1: 0 | JC1: 0 | JD1: 0 | JE1: 0 | JF1: 0 | JG1: 0 | JH1: 0 | JI1: 0 | JJ1: 0 | JK1: 0 | JL1: 0 | JM1: 0 | JN1: 0 | JO1: 0 | JP1: 0 | JQ1: 0 | JR1: 0 | JS1: 0 | JT1: 0 | JU1: 0 | JV1: 0 | JW1: 0 | JX1: 0 | JY1: 0 | JZ1: 0 | KA1: 0 | KB1: 0 | KC1: 0 | KD1: 0 | KE1: 0 | KF1: 0 | KG1: 0 | KH1: 0 | KI1: 0 | KJ1: 0 | KK1: 0 | KL1: 0 | KM1: 0 | KN1: 0 | KO1: 0 | KP1: 0 | KQ1: 0 | KR1: 0 | KS1: 0 | KT1: 0 | KU1: 0 | KV1: 0 | KW1: 0 | KX1: 0 | KY1: 0 | KZ1: 0 | LA1: 0 | LB1: 0 | LC1: 0 | LD1: 0 | LE1: 0 | LF1: 0 | LG1: 0 | LH1: 0 | LI1: 0 | LJ1: 0 | LK1: 0 | LL1: 0 | LM1: 0 | LN1: 0 | LO1: 0 | LP1: 0 | LQ1: 0 | LR1: 0 | LS1: 0 | LT1: 0 | LU1: 0 | LV1: 0 | LW1: 0 | LX1: 0 | LY1: 0 | LZ1: 0 | MA1: 0 | MB1: 0 | MC1: 0 | MD1: 0 | ME1: 0 | MF1: 0 | MG1: 0 | MH1: 0 | MI1: 0 | MJ1: 0 | MK1: 0 | ML1: 0 | MM1: 0 | MN1: 0 | MO1: 0 | MP1: 0 | MQ1: 0 | MR1: 0 | MS1: 0 | MT1: 0 | MU1: 0 | MV1: 0 | MW1: 0 | MX1: 0 | MY1: 0 | MZ1: 0 | NA1: 0 | NB1: 0 | NC1: 0 | ND1: 0 | NE1: 0 | NF1: 0 | NG1: 0 | NH1: 0 | NI1: 0 | NJ1: 0 | NK1: 0 | NL1: 0 | NM1: 0 | NN1: 0 | NO1: 0 | NP1: 0 | NQ1: 0 | NR1: 0 | NS1: 0 | NT1: 0 | NU1: 0 | NV1: 0 | NW1: 0 | NX1: 0 | NY1: 0 | NZ1: 0 | OA1: 0 | OB1: 0 | OC1: 0 | OD1: 0 | OE1: 0 | OF1: 0 | OG1: 0 | OH1: 0 | OI1: 0 | OJ1: 0 | OK1: 0 | OL1: 0 | OM1: 0 | ON1: 0 | OO1: 0 | OP1: 0 | OQ1: 0 | OR1: 0 | OS1: 0 | OT1: 0 | OU1: 0 | OV1: 0 | OW1: 0 | OX1: 0 | OY1: 0 | OZ1: 0 | PA1: 0 | PB1: 0 | PC1: 0 | PD1: 0 | PE1: 0 | PF1: 0 | PG1: 0 | PH1: 0 | PI1: 0 | PJ1: 0 | PK1: 0 | PL1: 0 | PM1: 0 | PN1: 0 | PO1: 0 | PP1: 0 | PQ1: 0 | PR1: 0 | PS1: 0 | PT1: 0 | PU1: 0 | PV1: 0 | PW1: 0 | PX1: 0 | PY1: 0 | PZ1: 0 | QA1: 0 | QB1: 0 | QC1: 0 | QD1: 0 | QE1: 0 | QF1: 0 | QG1: 0 | QH1: 0 | QI1: 0 | QJ1: 0 | QK1: 0 | QL1: 0 | QM1: 0 | QN1: 0 | QO1: 0 | QP1: 0 | QQ1: 0 | QR1: 0 | QS1: 0 | QT1: 0 | QU1: 0 | QV1: 0 | QW1: 0 | QX1: 0 | QY1: 0 | QZ1: 0 | RA1: 0 | RB1: 0 | RC1: 0 | RD1: 0 | RE1: 0 | RF1: 0 | RG1: 0 | RH1: 0 | RI1: 0 | RJ1: 0 | RK1: 0 | RL1: 0 | RM1: 0 | RN1: 0 | RO1: 0 | RP1: 0 | RQ1: 0 | RR1: 0 | RS1: 0 | RT1: 0 | RU1: 0 | RV1: 0 | RW1: 0 | RX1: 0 | RY1: 0 | RZ1: 0 | SA1: 0 | SB1: 0 | SC1: 0 | SD1: 0 | SE1: 0 | SF1: 0
B2: 名称 | C2: SKU | D2: 颜色 | E2: 尺寸 | F2: 45495 | G2: 45496 | H2: 45497 | I2: 45498 | J2: 45499 | K2: 45500 | L2: 45501 | M2: 45502 | N2: 45503 | O2: 45504 | P2: 45505 | Q2: 45506 | R2: 45507 | S2: 45508 | T2: 45509 | U2: 45510 | V2: 45511 | W2: 45512 | X2: 45513 | Y2: 45514 | Z2: 45515 | AA2: 45516 | AB2: 45517 | AC2: 45518 | AD2: 45519 | AE2: 45520 | AF2: 45521 | AG2: 45522 | AH2: 45523 | AI2: 45524 | AJ2: 45525 | AK2: 45526 | AL2: 45527 | AM2: 45528 | AN2: 45529 | AO2: 45530 | AP2: 45531 | AQ2: 45532 | AR2: 45533 | AS2: 45534 | AT2: 45535 | AU2: 45536 | AV2: 45537 | AW2: 45538 | AX2: 45539 | AY2: 45540 | AZ2: 45541 | BA2: 45542 | BB2: 45543 | BC2: 45544 | BD2: 45545 | BE2: 45546 | BF2: 45547 | BG2: 45548 | BH2: 45549 | BI2: 45550 | BJ2: 45551 | BK2: 45552 | BL2: 45553 | BM2: 45554 | BN2: 45555 | BO2: 45556 | BP2: 45557 | BQ2: 45558 | BR2: 45559 | BS2: 45560 | BT2: 45561 | BU2: 45562 | BV2: 45563 | BW2: 45564 | BX2: 45565 | BY2: 45566 | BZ2: 45567 | CA2: 45568 | CB2: 45569 | CC2: 45570 | CD2: 45571 | CE2: 45572 | CF2: 45573 | CG2: 45574 | CH2: 45575 | CI2: 45576 | CJ2: 45577 | CK2: 45578 | CL2: 45579 | CM2: 45580 | CN2: 45581 | CO2: 45582 | CP2: 45583 | CQ2: 45584 | CR2: 45585 | CS2: 45586 | CT2: 45587 | CU2: 45588 | CV2: 45589 | CW2: 45590 | CX2: 45591 | CY2: 45592 | CZ2: 45593 | DA2: 45594 | DB2: 45595 | DC2: 45596 | DD2: 45597 | DE2: 45598 | DF2: 0 | DG2: 0 | DH2: 0 | DI2: 0 | DJ2: 0 | DK2: 0 | DL2: 0 | DM2: 0 | DN2: 0 | DO2: 0 | DP2: 0 | DQ2: 0 | DR2: 0 | DS2: 0 | DT2: 0 | DU2: 0 | DV2: 0 | DW2: 0 | DX2: 0 | DY2: 0 | DZ2: 0 | EA2: 0 | EB2: 0 | EC2: 0 | ED2: 0 | EE2: 0 | EF2: 0 | EG2: 0 | EH2: 0 | EI2: 0 | EJ2: 0 | EK2: 0 | EL2: 0 | EM2: 0 | EN2: 0 | EO2: 0 | EP2: 0 | EQ2: 0 | ER2: 0 | ES2: 0 | ET2: 0 | EU2: 0 | EV2: 0 | EW2: 0 | EX2: 0 | EY2: 0 | EZ2: 0 | FA2: 0 | FB2: 0 | FC2: 0 | FD2: 0 | FE2: 0 | FF2: 0 | FG2: 0 | FH2: 0 | FI2: 0 | FJ2: 0 | FK2: 0 | FL2: 0 | FM2: 0 | FN2: 0 | FO2: 0 | FP2: 0 | FQ2: 0 | FR2: 0 | FS2: 0 | FT2: 0 | FU2: 0 | FV2: 0 | FW2: 0 | FX2: 0 | FY2: 0 | FZ2: 0 | GA2: 0 | GB2: 0 | GC2: 0 | GD2: 0 | GE2: 0 | GF2: 0 | GG2: 0 | GH2: 0 | GI2: 0 | GJ2: 0 | GK2: 0 | GL2: 0 | GM2: 0 | GN2: 0 | GO2: 0 | GP2: 0 | GQ2: 0 | GR2: 0 | GS2: 0 | GT2: 0 | GU2: 0 | GV2: 0 | GW2: 0 | GX2: 0 | GY2: 0 | GZ2: 0 | HA2: 0 | HB2: 0 | HC2: 0 | HD2: 0 | HE2: 0 | HF2: 0 | HG2: 0 | HH2: 0 | HI2: 0 | HJ2: 0 | HK2: 0 | HL2: 0 | HM2: 0 | HN2: 0 | HO2: 0 | HP2: 0 | HQ2: 0 | HR2: 0 | HS2: 0 | HT2: 0 | HU2: 0 | HV2: 0 | HW2: 0 | HX2: 0 | HY2: 0 | HZ2: 0 | IA2: 0 | IB2: 0 | IC2: 0 | ID2: 0 | IE2: 0 | IF2: 0 | IG2: 0 | IH2: 0 | II2: 0 | IJ2: 0 | IK2: 0 | IL2: 0 | IM2: 0 | IN2: 0 | IO2: 0 | IP2: 0 | IQ2: 0 | IR2: 0 | IS2: 0 | IT2: 0 | IU2: 0 | IV2: 0 | IW2: 0 | IX2: 0 | IY2: 0 | IZ2: 0 | JA2: 0 | JB2: 0 | JC2: 0 | JD2: 0 | JE2: 0 | JF2: 0 | JG2: 0 | JH2: 0 | JI2: 0 | JJ2: 0 | JK2: 0 | JL2: 0 | JM2: 0 | JN2: 0 | JO2: 0 | JP2: 0 | JQ2: 0 | JR2: 0 | JS2: 0 | JT2: 0 | JU2: 0 | JV2: 0 | JW2: 0 | JX2: 0 | JY2: 0 | JZ2: 0 | KA2: 0 | KB2: 0 | KC2: 0 | KD2: 0 | KE2: 0 | KF2: 0 | KG2: 0 | KH2: 0 | KI2: 0 | KJ2: 0 | KK2: 0 | KL2: 0 | KM2: 0 | KN2: 0 | KO2: 0 | KP2: 0 | KQ2: 0 | KR2: 0 | KS2: 0 | KT2: 0 | KU2: 0 | KV2: 0 | KW2: 0 | KX2: 0 | KY2: 0 | KZ2: 0 | LA2: 0 | LB2: 0 | LC2: 0 | LD2: 0 | LE2: 0 | LF2: 0 | LG2: 0 | LH2: 0 | LI2: 0 | LJ2: 0 | LK2: 0 | LL2: 0 | LM2: 0 | LN2: 0 | LO2: 0 | LP2: 0 | LQ2: 0 | LR2: 0 | LS2: 0 | LT2: 0 | LU2: 0 | LV2: 0 | LW2: 0 | LX2: 0 | LY2: 0 | LZ2: 0 | MA2: 0 | MB2: 0 | MC2: 0 | MD2: 0 | ME2: 0 | MF2: 0 | MG2: 0 | MH2: 0 | MI2: 0 | MJ2: 0 | MK2: 0 | ML2: 0 | MM2: 0 | MN2: 0 | MO2: 0 | MP2: 0 | MQ2: 0 | MR2: 0 | MS2: 0 | MT2: 0 | MU2: 0 | MV2: 0 | MW2: 0 | MX2: 0 | MY2: 0 | MZ2: 0 | NA2: 0 | NB2: 0 | NC2: 0 | ND2: 0 | NE2: 0 | NF2: 0 | NG2: 0 | NH2: 0 | NI2: 0 | NJ2: 0 | NK2: 0 | NL2: 0 | NM2: 0 | NN2: 0 | NO2: 0 | NP2: 0 | NQ2: 0 | NR2: 0 | NS2: 0 | NT2: 0 | NU2: 0 | NV2: 0 | NW2: 0 | NX2: 0 | NY2: 0 | NZ2: 0 | OA2: 0 | OB2: 0 | OC2: 0 | OD2: 0 | OE2: 0 | OF2: 0 | OG2: 0 | OH2: 0 | OI2: 0 | OJ2: 0 | OK2: 0 | OL2: 0 | OM2: 0 | ON2: 0 | OO2: 0 | OP2: 0 | OQ2: 0 | OR2: 0 | OS2: 0 | OT2: 0 | OU2: 0 | OV2: 0 | OW2: 0 | OX2: 0 | OY2: 0 | OZ2: 0 | PA2: 0 | PB2: 0 | PC2: 0 | PD2: 0 | PE2: 0 | PF2: 0 | PG2: 0 | PH2: 0 | PI2: 0 | PJ2: 0 | PK2: 0 | PL2: 0 | PM2: 0 | PN2: 0 | PO2: 0 | PP2: 0 | PQ2: 0 | PR2: 0 | PS2: 0 | PT2: 0 | PU2: 0 | PV2: 0 | PW2: 0 | PX2: 0 | PY2: 0 | PZ2: 0 | QA2: 0 | QB2: 0 | QC2: 0 | QD2: 0 | QE2: 0 | QF2: 0 | QG2: 0 | QH2: 0 | QI2: 0 | QJ2: 0 | QK2: 0 | QL2: 0 | QM2: 0 | QN2: 0 | QO2: 0 | QP2: 0 | QQ2: 0 | QR2: 0 | QS2: 0 | QT2: 0 | QU2: 0 | QV2: 0 | QW2: 0 | QX2: 0 | QY2: 0 | QZ2: 0 | RA2: 0 | RB2: 0 | RC2: 0 | RD2: 0 | RE2: 0 | RF2: 0 | RG2: 0 | RH2: 0 | RI2: 0 | RJ2: 0 | RK2: 0 | RL2: 0 | RM2: 0 | RN2: 0 | RO2: 0 | RP2: 0 | RQ2: 0 | RR2: 0 | RS2: 0 | RT2: 0 | RU2: 0 | RV2: 0 | RW2: 0 | RX2: 0 | RY2: 0 | RZ2: 0 | SA2: 0 | SB2: 0 | SC2: 0 | SD2: 0 | SE2: 0 | SF2: 0
B3: 0 | C3: 0 | D3: 0 | E3: 对应到货批次 | F3: 0 | G3: 0 | H3: 0 | I3: 0 | J3: 7/29批次 | K3: 7/29批次 | L3: 8/5批次 | M3: 8/5批次 | N3: 8/5批次 | O3: 8/5批次 | P3: 8/5批次 | Q3: 8/5批次 | R3: 8/5批次 | S3: 8/5批次 | T3: 8/10批次 | U3: 8/10批次 | V3: 8/10批次 | W3: 8/10批次 | X3: 8/10批次 | Y3: 8/16批次 | Z3: 8/16批次 | AA3: 8/16批次 | AB3: 8/16批次 | AC3: 8/16批次 | AD3: 8/16批次 | AE3: 8/20批次 | AF3: 8/20批次 | AG3: 0 | AH3: 8/20批次 | AI3: 8/25批次 | AJ3: 8/25批次 | AK3: 8/25批次 | AL3: 8/25批次 | AM3: 8/25批次 | AN3: 8/30批次 | AO3: 8/30批次 | AP3: 8/30批次 | AQ3: 8/30批次 | AR3: 8/30批次 | AS3: 9/3批次 | AT3: 9/3批次 | AU3: 9/3批次 | AV3: 9/3批次 | AW3: 9/7批次 | AX3: 9/7批次 | AY3: 9/7批次 | AZ3: 9/7批次 | BA3: 9/11批次 | BB3: 9/11批次 | BC3: 9/11批次 | BD3: 9/11批次 | BE3: 9/15批次 | BF3: 9/15批次 | BG3: 9/15批次 | BH3: 9/15批次 | BI3: 9/20批次 | BJ3: 9/20批次 | BK3: 0 | BL3: 9/20批次 | BM3: 9/20批次 | BN3: 9/27批次 | BO3: 9/27批次 | BP3: 9/27批次 | BQ3: 9/27批次 | BR3: 9/27批次 | BS3: 9/27批次 | BT3: 9/27批次 | BU3: 9/30批次 | BV3: 9/30批次 | BW3: 10/10批次 | BX3: 10/10批次 | BY3: 0 | BZ3: 0 | CA3: 10/10批次 | CB3: 10/10批次 | CC3: 10/10批次 | CD3: 10/10批次 | CE3: 10/10批次 | CF3: 10/10批次 | CG3: 10/10批次 | CH3: 10/14批次 | CI3: 10/14批次 | CJ3: 10/14批次 | CK3: 10/14批次 | CL3: 10/18批次 | CM3: 10/18批次 | CN3: 10/18批次 | CO3: 10/18批次 | CP3: 0 | CQ3: 0 | CR3: 0 | CS3: 0 | CT3: 0 | CU3: 0 | CV3: 0 | CW3: 0 | CX3: 0 | CY3: 0 | CZ3: 0 | DA3: 0 | DB3: 0 | DC3: 0 | DD3: 0 | DE3: 0 | DF3: 0 | DG3: 0 | DH3: 0 | DI3: 0 | DJ3: 0 | DK3: 0 | DL3: 0 | DM3: 0 | DN3: 0 | DO3: 0 | DP3: 0 | DQ3: 0 | DR3: 0 | DS3: 0 | DT3: 0 | DU3: 0 | DV3: 0 | DW3: 0 | DX3: 0 | DY3: 0 | DZ3: 0 | EA3: 0 | EB3: 0 | EC3: 0 | ED3: 0 | EE3: 0 | EF3: 0 | EG3: 0 | EH3: 0 | EI3: 0 | EJ3: 0 | EK3: 0 | EL3: 0 | EM3: 0 | EN3: 0 | EO3: 0 | EP3: 0 | EQ3: 0 | ER3: 0 | ES3: 0 | ET3: 0 | EU3: 0 | EV3: 0 | EW3: 0 | EX3: 0 | EY3: 0 | EZ3: 0 | FA3: 0 | FB3: 0 | FC3: 0 | FD3: 0 | FE3: 0 | FF3: 0 | FG3: 0 | FH3: 0 | FI3: 0 | FJ3: 0 | FK3: 0 | FL3: 0 | FM3: 0 | FN3: 0 | FO3: 0 | FP3: 0 | FQ3: 0 | FR3: 0 | FS3: 0 | FT3: 0 | FU3: 0 | FV3: 0 | FW3: 0 | FX3: 0 | FY3: 0 | FZ3: 0 | GA3: 0 | GB3: 0 | GC3: 0 | GD3: 0 | GE3: 0 | GF3: 0 | GG3: 0 | GH3: 0 | GI3: 0 | GJ3: 0 | GK3: 0 | GL3: 0 | GM3: 0 | GN3: 0 | GO3: 0 | GP3: 0 | GQ3: 0 | GR3: 0 | GS3: 0 | GT3: 0 | GU3: 0 | GV3: 0 | GW3: 0 | GX3: 0 | GY3: 0 | GZ3: 0 | HA3: 0 | HB3: 0 | HC3: 0 | HD3: 0 | HE3: 0 | HF3: 0 | HG3: 0 | HH3: 0 | HI3: 0 | HJ3: 0 | HK3: 0 | HL3: 0 | HM3: 0 | HN3: 0 | HO3: 0 | HP3: 0 | HQ3: 0 | HR3: 0 | HS3: 0 | HT3: 0 | HU3: 0 | HV3: 0 | HW3: 0 | HX3: 0 | HY3: 0 | HZ3: 0 | IA3: 0 | IB3: 0 | IC3: 0 | ID3: 0 | IE3: 0 | IF3: 0 | IG3: 0 | IH3: 0 | II3: 0 | IJ3: 0 | IK3: 0 | IL3: 0 | IM3: 0 | IN3: 0 | IO3: 0 | IP3: 0 | IQ3: 0 | IR3: 0 | IS3: 0 | IT3: 0 | IU3: 0 | IV3: 0 | IW3: 0 | IX3: 0 | IY3: 0 | IZ3: 0 | JA3: 0 | JB3: 0 | JC3: 0 | JD3: 0 | JE3: 0 | JF3: 0 | JG3: 0 | JH3: 0 | JI3: 0 | JJ3: 0 | JK3: 0 | JL3: 0 | JM3: 0 | JN3: 0 | JO3: 0 | JP3: 0 | JQ3: 0 | JR3: 0 | JS3: 0 | JT3: 0 | JU3: 0 | JV3: 0 | JW3: 0 | JX3: 0 | JY3: 0 | JZ3: 0 | KA3: 0 | KB3: 0 | KC3: 0 | KD3: 0 | KE3: 0 | KF3: 0 | KG3: 0 | KH3: 0 | KI3: 0 | KJ3: 0 | KK3: 0 | KL3: 0 | KM3: 0 | KN3: 0 | KO3: 0 | KP3: 0 | KQ3: 0 | KR3: 0 | KS3: 0 | KT3: 0 | KU3: 0 | KV3: 0 | KW3: 0 | KX3: 0 | KY3: 0 | KZ3: 0 | LA3: 0 | LB3: 0 | LC3: 0 | LD3: 0 | LE3: 0 | LF3: 0 | LG3: 0 | LH3: 0 | LI3: 0 | LJ3: 0 | LK3: 0 | LL3: 0 | LM3: 0 | LN3: 0 | LO3: 0 | LP3: 0 | LQ3: 0 | LR3: 0 | LS3: 0 | LT3: 0 | LU3: 0 | LV3: 0 | LW3: 0 | LX3: 0 | LY3: 0 | LZ3: 0 | MA3: 0 | MB3: 0 | MC3: 0 | MD3: 0 | ME3: 0 | MF3: 0 | MG3: 0 | MH3: 0 | MI3: 0 | MJ3: 0 | MK3: 0 | ML3: 0 | MM3: 0 | MN3: 0 | MO3: 0 | MP3: 0 | MQ3: 0 | MR3: 0 | MS3: 0 | MT3: 0 | MU3: 0 | MV3: 0 | MW3: 0 | MX3: 0 | MY3: 0 | MZ3: 0 | NA3: 0 | NB3: 0 | NC3: 0 | ND3: 0 | NE3: 0 | NF3: 0 | NG3: 0 | NH3: 0 | NI3: 0 | NJ3: 0 | NK3: 0 | NL3: 0 | NM3: 0 | NN3: 0 | NO3: 0 | NP3: 0 | NQ3: 0 | NR3: 0 | NS3: 0 | NT3: 0 | NU3: 0 | NV3: 0 | NW3: 0 | NX3: 0 | NY3: 0 | NZ3: 0 | OA3: 0 | OB3: 0 | OC3: 0 | OD3: 0 | OE3: 0 | OF3: 0 | OG3: 0 | OH3: 0 | OI3: 0 | OJ3: 0 | OK3: 0 | OL3: 0 | OM3: 0 | ON3: 0 | OO3: 0 | OP3: 0 | OQ3: 0 | OR3: 0 | OS3: 0 | OT3: 0 | OU3: 0 | OV3: 0 | OW3: 0 | OX3: 0 | OY3: 0 | OZ3: 0 | PA3: 0 | PB3: 0 | PC3: 0 | PD3: 0 | PE3: 0 | PF3: 0 | PG3: 0 | PH3: 0 | PI3: 0 | PJ3: 0 | PK3: 0 | PL3: 0 | PM3: 0 | PN3: 0 | PO3: 0 | PP3: 0 | PQ3: 0 | PR3: 0 | PS3: 0 | PT3: 0 | PU3: 0 | PV3: 0 | PW3: 0 | PX3: 0 | PY3: 0 | PZ3: 0 | QA3: 0 | QB3: 0 | QC3: 0 | QD3: 0 | QE3: 0 | QF3: 0 | QG3: 0 | QH3: 0 | QI3: 0 | QJ3: 0 | QK3: 0 | QL3: 0 | QM3: 0 | QN3: 0 | QO3: 0 | QP3: 0 | QQ3: 0 | QR3: 0 | QS3: 0 | QT3: 0 | QU3: 0 | QV3: 0 | QW3: 0 | QX3: 0 | QY3: 0 | QZ3: 0 | RA3: 0 | RB3: 0 | RC3: 0 | RD3: 0 | RE3: 0 | RF3: 0 | RG3: 0 | RH3: 0 | RI3: 0 | RJ3: 0 | RK3: 0 | RL3: 0 | RM3: 0 | RN3: 0 | RO3: 0 | RP3: 0 | RQ3: 0 | RR3: 0 | RS3: 0 | RT3: 0 | RU3: 0 | RV3: 0 | RW3: 0 | RX3: 0 | RY3: 0 | RZ3: 0 | SA3: 0 | SB3: 0 | SC3: 0 | SD3: 0 | SE3: 0 | SF3: 0
B4: 亚朵星球 深睡控温被PRO·四季 | C4: 12800025601141516 | D4: 深空蓝 | E4: 150*200cm | F4: 0 | G4: 0 | H4: 0 | I4: 0 | J4: 0 | K4: 0 | L4: 0 | M4: 0 | N4: 0 | O4: 0 | P4: 0 | Q4: 0 | R4: 0 | S4: 0 | T4: 0 | U4: 0 | V4: 0 | W4: 0 | X4: 0 | Y4: 0 | Z4: 0 | AA4: 0 | AB4: 0 | AC4: 0 | AD4: 0 | AE4: 0 | AF4: 0 | AG4: 0 | AH4: 0 | AI4: 0 | AJ4: 0 | AK4: 39 | AL4: 83 | AM4: 93 | AN4: 96 | AO4: 55 | AP4: 131 | AQ4: 62 | AR4: 226 | AS4: 0 | AT4: 212 | AU4: 0 | AV4: 18 | AW4: 173 | AX4: 270 | AY4: 263 | AZ4: 328 | BA4: 304 | BB4: 52 | BC4: 60 | BD4: 52 | BE4: 8 | BF4: 0 | BG4: 318 | BH4: 491 | BI4: 75 | BJ4: 3 | BK4: 0 | BL4: 295 | BM4: 548 | BN4: 208 | BO4: 187 | BP4: 334 | BQ4: 54 | BR4: 587 | BS4: 321 | BT4: 260 | BU4: 191 | BV4: 3 | BW4: 0 | BX4: 29 | BY4: 0 | BZ4: 0 | CA4: 114 | CB4: 56 | CC4: 258 | CD4: 204 | CE4: 279 | CF4: 97 | CG4: 1 | CH4: 0 | CI4: 149 | CJ4: 2 | CK4: 148 | CL4: 1 | CM4: 16 | CN4: 260 | CO4: 397 | CP4: 142 | CQ4: 0 | CR4: 38 | CS4: 0 | CT4: 0 | CU4: 0 | CV4: 0 | CW4: 0 | CX4: 0 | CY4: 0 | CZ4: 0 | DA4: 0 | DB4: 0 | DC4: 0 | DD4: 0 | DE4: 0 | DF4: 0 | DG4: 0 | DH4: 0 | DI4: 0 | DJ4: 0 | DK4: 0 | DL4: 0 | DM4: 0 | DN4: 0 | DO4: 0 | DP4: 0 | DQ4: 0 | DR4: 0 | DS4: 0 | DT4: 0 | DU4: 0 | DV4: 0 | DW4: 0 | DX4: 0 | DY4: 0 | DZ4: 0 | EA4: 0 | EB4: 0 | EC4: 0 | ED4: 0 | EE4: 0 | EF4: 0 | EG4: 0 | EH4: 0 | EI4: 0 | EJ4: 0 | EK4: 0 | EL4: 0 | EM4: 0 | EN4: 0 | EO4: 0 | EP4: 0 | EQ4: 0 | ER4: 0 | ES4: 0 | ET4: 0 | EU4: 0 | EV4: 0 | EW4: 0 | EX4: 0 | EY4: 0 | EZ4: 0 | FA4: 0 | FB4: 0 | FC4: 0 | FD4: 0 | FE4: 0 | FF4: 0 | FG4: 0 | FH4: 0 | FI4: 0 | FJ4: 0 | FK4: 0 | FL4: 0 | FM4: 0 | FN4: 0 | FO4: 0 | FP4: 0 | FQ4: 0 | FR4: 0 | FS4: 0 | FT4: 0 | FU4: 0 | FV4: 0 | FW4: 0 | FX4: 0 | FY4: 0 | FZ4: 0 | GA4: 0 | GB4: 0 | GC4: 0 | GD4: 0 | GE4: 0 | GF4: 0 | GG4: 0 | GH4: 0 | GI4: 0 | GJ4: 0 | GK4: 0 | GL4: 0 | GM4: 0 | GN4: 0 | GO4: 0 | GP4: 0 | GQ4: 0 | GR4: 0 | GS4: 0 | GT4: 0 | GU4: 0 | GV4: 0 | GW4: 0 | GX4: 0 | GY4: 0 | GZ4: 0 | HA4: 0 | HB4: 0 | HC4: 0 | HD4: 0 | HE4: 0 | HF4: 0 | HG4: 0 | HH4: 0 | HI4: 0 | HJ4: 0 | HK4: 0 | HL4: 0 | HM4: 0 | HN4: 0 | HO4: 0 | HP4: 0 | HQ4: 0 | HR4: 0 | HS4: 0 | HT4: 0 | HU4: 0 | HV4: 0 | HW4: 0 | HX4: 0 | HY4: 0 | HZ4: 0 | IA4: 0 | IB4: 0 | IC4: 0 | ID4: 0 | IE4: 0 | IF4: 0 | IG4: 0 | IH4: 0 | II4: 0 | IJ4: 0 | IK4: 0 | IL4: 0 | IM4: 0 | IN4: 0 | IO4: 0 | IP4: 0 | IQ4: 0 | IR4: 0 | IS4: 0 | IT4: 0 | IU4: 0 | IV4: 0 | IW4: 0 | IX4: 0 | IY4: 0 | IZ4: 0 | JA4: 0 | JB4: 0 | JC4: 0 | JD4: 0 | JE4: 0 | JF4: 0 | JG4: 0 | JH4: 0 | JI4: 0 | JJ4: 0 | JK4: 0 | JL4: 0 | JM4: 0 | JN4: 0 | JO4: 0 | JP4: 0 | JQ4: 0 | JR4: 0 | JS4: 0 | JT4: 0 | JU4: 0 | JV4: 0 | JW4: 0 | JX4: 0 | JY4: 0 | JZ4: 0 | KA4: 0 | KB4: 0 | KC4: 0 | KD4: 0 | KE4: 0 | KF4: 0 | KG4: 0 | KH4: 0 | KI4: 0 | KJ4: 0 | KK4: 0 | KL4: 0 | KM4: 0 | KN4: 0 | KO4: 0 | KP4: 0 | KQ4: 0 | KR4: 0 | KS4: 0 | KT4: 0 | KU4: 0 | KV4: 0 | KW4: 0 | KX4: 0 | KY4: 0 | KZ4: 0 | LA4: 0 | LB4: 0 | LC4: 0 | LD4: 0 | LE4: 0 | LF4: 0 | LG4: 0 | LH4: 0 | LI4: 0 | LJ4: 0 | LK4: 0 | LL4: 0 | LM4: 0 | LN4: 0 | LO4: 0 | LP4: 0 | LQ4: 0 | LR4: 0 | LS4: 0 | LT4: 0 | LU4: 0 | LV4: 0 | LW4: 0 | LX4: 0 | LY4: 0 | LZ4: 0 | MA4: 0 | MB4: 0 | MC4: 0 | MD4: 0 | ME4: 0 | MF4: 0 | MG4: 0 | MH4: 0 | MI4: 0 | MJ4: 0 | MK4: 0 | ML4: 0 | MM4: 0 | MN4: 0 | MO4: 0 | MP4: 0 | MQ4: 0 | MR4: 0 | MS4: 0 | MT4: 0 | MU4: 0 | MV4: 0 | MW4: 0 | MX4: 0 | MY4: 0 | MZ4: 0 | NA4: 0 | NB4: 0 | NC4: 0 | ND4: 0 | NE4: 0 | NF4: 0 | NG4: 0 | NH4: 0 | NI4: 0 | NJ4: 0 | NK4: 0 | NL4: 0 | NM4: 0 | NN4: 0 | NO4: 0 | NP4: 0 | NQ4: 0 | NR4: 0 | NS4: 0 | NT4: 0 | NU4: 0 | NV4: 0 | NW4: 0 | NX4: 0 | NY4: 0 | NZ4: 0 | OA4: 0 | OB4: 0 | OC4: 0 | OD4: 0 | OE4: 0 | OF4: 0 | OG4: 0 | OH4: 0 | OI4: 0 | OJ4: 0 | OK4: 0 | OL4: 0 | OM4: 0 | ON4: 0 | OO4: 0 | OP4: 0 | OQ4: 0 | OR4: 0 | OS4: 0 | OT4: 0 | OU4: 0 | OV4: 0 | OW4: 0 | OX4: 0 | OY4: 0 | OZ4: 0 | PA4: 0 | PB4: 0 | PC4: 0 | PD4: 0 | PE4: 0 | PF4: 0 | PG4: 0 | PH4: 0 | PI4: 0 | PJ4: 0 | PK4: 0 | PL4: 0 | PM4: 0 | PN4: 0 | PO4: 0 | PP4: 0 | PQ4: 0 | PR4: 0 | PS4: 0 | PT4: 0 | PU4: 0 | PV4: 0 | PW4: 0 | PX4: 0 | PY4: 0 | PZ4: 0 | QA4: 0 | QB4: 0 | QC4: 0 | QD4: 0 | QE4: 0 | QF4: 0 | QG4: 0 | QH4: 0 | QI4: 0 | QJ4: 0 | QK4: 0 | QL4: 0 | QM4: 0 | QN4: 0 | QO4: 0 | QP4: 0 | QQ4: 0 | QR4: 0 | QS4: 0 | QT4: 0 | QU4: 0 | QV4: 0 | QW4: 0 | QX4: 0 | QY4: 0 | QZ4: 0 | RA4: 0 | RB4: 0 | RC4: 0 | RD4: 0 | RE4: 0 | RF4: 0 | RG4: 0 | RH4: 0 | RI4: 0 | RJ4: 0 | RK4: 0 | RL4: 0 | RM4: 0 | RN4: 0 | RO4: 0 | RP4: 0 | RQ4: 0 | RR4: 0 | RS4: 0 | RT4: 0 | RU4: 0 | RV4: 0 | RW4: 0 | RX4: 0 | RY4: 0 | RZ4: 0 | SA4: 0 | SB4: 0 | SC4: 0 | SD4: 0 | SE4: 0 | SF4: 0
B5: 0 | C5: 12800025601141514 | D5: 0 | E5: 200*230cm | F5: 0 | G5: 0 | H5: 0 | I5: 0 | J5: 0 | K5: 0 | L5: 0 | M5: 0 | N5: 0 | O5: 0 | P5: 0 | Q5: 0 | R5: 0 | S5: 0 | T5: 0 | U5: 0 | V5: 0 | W5: 0 | X5: 0 | Y5: 0 | Z5: 0 | AA5: 0 | AB5: 40 | AC5: 147 | AD5: 27 | AE5: 66 | AF5: 37 | AG5: 0 | AH5: 100 | AI5: 0 | AJ5: 62 | AK5: 69 | AL5: 95 | AM5: 417 | AN5: 140 | AO5: 124 | AP5: 393 | AQ5: 387 | AR5: 343 | AS5: 141 | AT5: 414 | AU5: 448 | AV5: 241 | AW5: 706 | AX5: 517 | AY5: 402 | AZ5: 93 | BA5: 204 | BB5: 270 | BC5: 349 | BD5: 189 | BE5: 598 | BF5: 579 | BG5: 323 | BH5: 117 | BI5: 624 | BJ5: 384 | BK5: 0 | BL5: 173 | BM5: 150 | BN5: 52 | BO5: 522 | BP5: 251 | BQ5: 418 | BR5: 442 | BS5: 131 | BT5: 249 | BU5: 50 | BV5: 1 | BW5: 116 | BX5: 59 | BY5: 0 | BZ5: 0 | CA5: 82 | CB5: 216 | CC5: 66 | CD5: 284 | CE5: 148 | CF5: 150 | CG5: 141 | CH5: 1 | CI5: 281 | CJ5: 195 | CK5: 199 | CL5: 70 | CM5: 203 | CN5: 528 | CO5: 395 | CP5: 536 | CQ5: 79 | CR5: 248 | CS5: 0 | CT5: 139 | CU5: 0 | CV5: 232 | CW5: 314 | CX5: 0 | CY5: 184 | CZ5: 0 | DA5: 0 | DB5: 0 | DC5: 0 | DD5: 0 | DE5: 0 | DF5: 0 | DG5: 0 | DH5: 0 | DI5: 0 | DJ5: 0 | DK5: 0 | DL5: 0 | DM5: 0 | DN5: 0 | DO5: 0 | DP5: 0 | DQ5: 0 | DR5: 0 | DS5: 0 | DT5: 0 | DU5: 0 | DV5: 0 | DW5: 0 | DX5: 0 | DY5: 0 | DZ5: 0 | EA5: 0 | EB5: 0 | EC5: 0 | ED5: 0 | EE5: 0 | EF5: 0 | EG5: 0 | EH5: 0 | EI5: 0 | EJ5: 0 | EK5: 0 | EL5: 0 | EM5: 0 | EN5: 0 | EO5: 0 | EP5: 0 | EQ5: 0 | ER5: 0 | ES5: 0 | ET5: 0 | EU5: 0 | EV5: 0 | EW5: 0 | EX5: 0 | EY5: 0 | EZ5: 0 | FA5: 0 | FB5: 0 | FC5: 0 | FD5: 0 | FE5: 0 | FF5: 0 | FG5: 0 | FH5: 0 | FI5: 0 | FJ5: 0 | FK5: 0 | FL5: 0 | FM5: 0 | FN5: 0 | FO5: 0 | FP5: 0 | FQ5: 0 | FR5: 0 | FS5: 0 | FT5: 0 | FU5: 0 | FV5: 0 | FW5: 0 | FX5: 0 | FY5: 0 | FZ5: 0 | GA5: 0 | GB5: 0 | GC5: 0 | GD5: 0 | GE5: 0 | GF5: 0 | GG5: 0 | GH5: 0 | GI5: 0 | GJ5: 0 | GK5: 0 | GL5: 0 | GM5: 0 | GN5: 0 | GO5: 0 | GP5: 0 | GQ5: 0 | GR5: 0 | GS5: 0 | GT5: 0 | GU5: 0 | GV5: 0 | GW5: 0 | GX5: 0 | GY5: 0 | GZ5: 0 | HA5: 0 | HB5: 0 | HC5: 0 | HD5: 0 | HE5: 0 | HF5: 0 | HG5: 0 | HH5: 0 | HI5: 0 | HJ5: 0 | HK5: 0 | HL5: 0 | HM5: 0 | HN5: 0 | HO5: 0 | HP5: 0 | HQ5: 0 | HR5: 0 | HS5: 0 | HT5: 0 | HU5: 0 | HV5: 0 | HW5: 0 | HX5: 0 | HY5: 0 | HZ5: 0 | IA5: 0 | IB5: 0 | IC5: 0 | ID5: 0 | IE5: 0 | IF5: 0 | IG5: 0 | IH5: 0 | II5: 0 | IJ5: 0 | IK5: 0 | IL5: 0 | IM5: 0 | IN5: 0 | IO5: 0 | IP5: 0 | IQ5: 0 | IR5: 0 | IS5: 0 | IT5: 0 | IU5: 0 | IV5: 0 | IW5: 0 | IX5: 0 | IY5: 0 | IZ5: 0 | JA5: 0 | JB5: 0 | JC5: 0 | JD5: 0 | JE5: 0 | JF5: 0 | JG5: 0 | JH5: 0 | JI5: 0 | JJ5: 0 | JK5: 0 | JL5: 0 | JM5: 0 | JN5: 0 | JO5: 0 | JP5: 0 | JQ5: 0 | JR5: 0 | JS5: 0 | JT5: 0 | JU5: 0 | JV5: 0 | JW5: 0 | JX5: 0 | JY5: 0 | JZ5: 0 | KA5: 0 | KB5: 0 | KC5: 0 | KD5: 0 | KE5: 0 | KF5: 0 | KG5: 0 | KH5: 0 | KI5: 0 | KJ5: 0 | KK5: 0 | KL5: 0 | KM5: 0 | KN5: 0 | KO5: 0 | KP5: 0 | KQ5: 0 | KR5: 0 | KS5: 0 | KT5: 0 | KU5: 0 | KV5: 0 | KW5: 0 | KX5: 0 | KY5: 0 | KZ5: 0 | LA5: 0 | LB5: 0 | LC5: 0 | LD5: 0 | LE5: 0 | LF5: 0 | LG5: 0 | LH5: 0 | LI5: 0 | LJ5: 0 | LK5: 0 | LL5: 0 | LM5: 0 | LN5: 0 | LO5: 0 | LP5: 0 | LQ5: 0 | LR5: 0 | LS5: 0 | LT5: 0 | LU5: 0 | LV5: 0 | LW5: 0 | LX5: 0 | LY5: 0 | LZ5: 0 | MA5: 0 | MB5: 0 | MC5: 0 | MD5: 0 | ME5: 0 | MF5: 0 | MG5: 0 | MH5: 0 | MI5: 0 | MJ5: 0 | MK5: 0 | ML5: 0 | MM5: 0 | MN5: 0 | MO5: 0 | MP5: 0 | MQ5: 0 | MR5: 0 | MS5: 0 | MT5: 0 | MU5: 0 | MV5: 0 | MW5: 0 | MX5: 0 | MY5: 0 | MZ5: 0 | NA5: 0 | NB5: 0 | NC5: 0 | ND5: 0 | NE5: 0 | NF5: 0 | NG5: 0 | NH5: 0 | NI5: 0 | NJ5: 0 | NK5: 0 | NL5: 0 | NM5: 0 | NN5: 0 | NO5: 0 | NP5: 0 | NQ5: 0 | NR5: 0 | NS5: 0 | NT5: 0 | NU5: 0 | NV5: 0 | NW5: 0 | NX5: 0 | NY5: 0 | NZ5: 0 | OA5: 0 | OB5: 0 | OC5: 0 | OD5: 0 | OE5: 0 | OF5: 0 | OG5: 0 | OH5: 0 | OI5: 0 | OJ5: 0 | OK5: 0 | OL5: 0 | OM5: 0 | ON5: 0 | OO5: 0 | OP5: 0 | OQ5: 0 | OR5: 0 | OS5: 0 | OT5: 0 | OU5: 0 | OV5: 0 | OW5: 0 | OX5: 0 | OY5: 0 | OZ5: 0 | PA5: 0 | PB5: 0 | PC5: 0 | PD5: 0 | PE5: 0 | PF5: 0 | PG5: 0 | PH5: 0 | PI5: 0 | PJ5: 0 | PK5: 0 | PL5: 0 | PM5: 0 | PN5: 0 | PO5: 0 | PP5: 0 | PQ5: 0 | PR5: 0 | PS5: 0 | PT5: 0 | PU5: 0 | PV5: 0 | PW5: 0 | PX5: 0 | PY5: 0 | PZ5: 0 | QA5: 0 | QB5: 0 | QC5: 0 | QD5: 0 | QE5: 0 | QF5: 0 | QG5: 0 | QH5: 0 | QI5: 0 | QJ5: 0 | QK5: 0 | QL5: 0 | QM5: 0 | QN5: 0 | QO5: 0 | QP5: 0 | QQ5: 0 | QR5: 0 | QS5: 0 | QT5: 0 | QU5: 0 | QV5: 0 | QW5: 0 | QX5: 0 | QY5: 0 | QZ5: 0 | RA5: 0 | RB5: 0 | RC5: 0 | RD5: 0 | RE5: 0 | RF5: 0 | RG5: 0 | RH5: 0 | RI5: 0 | RJ5: 0 | RK5: 0 | RL5: 0 | RM5: 0 | RN5: 0 | RO5: 0 | RP5: 0 | RQ5: 0 | RR5: 0 | RS5: 0 | RT5: 0 | RU5: 0 | RV5: 0 | RW5: 0 | RX5: 0 | RY5: 0 | RZ5: 0 | SA5: 0 | SB5: 0 | SC5: 0 | SD5: 0 | SE5: 0 | SF5: 0
B6: 0 | C6: 12800025601141513 | D6: 0 | E6: 220*240cm | F6: 0 | G6: 0 | H6: 0 | I6: 0 | J6: 0 | K6: 0 | L6: 0 | M6: 0 | N6: 0 | O6: 0 | P6: 0 | Q6: 0 | R6: 0 | S6: 0 | T6: 0 | U6: 0 | V6: 0 | W6: 0 | X6: 0 | Y6: 0 | Z6: 0 | AA6: 0 | AB6: 0 | AC6: 0 | AD6: 0 | AE6: 0 | AF6: 0 | AG6: 0 | AH6: 0 | AI6: 0 | AJ6: 0 | AK6: 24 | AL6: 25 | AM6: 212 | AN6: 40 | AO6: 115 | AP6: 33 | AQ6: 211 | AR6: 213 | AS6: 172 | AT6: 209 | AU6: 262 | AV6: 43 | AW6: 61 | AX6: 82 | AY6: 71 | AZ6: 119 | BA6: 150 | BB6: 75 | BC6: 85 | BD6: 0 | BE6: 44 | BF6: 30 | BG6: 276 | BH6: 278 | BI6: 28 | BJ6: 164 | BK6: 0 | BL6: 168 | BM6: 446 | BN6: 211 | BO6: 177 | BP6: 61 | BQ6: 361 | BR6: 193 | BS6: 331 | BT6: 233 | BU6: 75 | BV6: 4 | BW6: 40 | BX6: 118 | BY6: 0 | BZ6: 0 | CA6: 156 | CB6: 162 | CC6: 171 | CD6: 86 | CE6: 85 | CF6: 107 | CG6: 23 | CH6: 6 | CI6: 14 | CJ6: 11 | CK6: 0 | CL6: 90 | CM6: 308 | CN6: 169 | CO6: 174 | CP6: 255 | CQ6: 6 | CR6: 0 | CS6: 0 | CT6: 0 | CU6: 0 | CV6: 0 | CW6: 0 | CX6: 0 | CY6: 0 | CZ6: 0 | DA6: 0 | DB6: 0 | DC6: 0 | DD6: 0 | DE6: 0 | DF6: 0 | DG6: 0 | DH6: 0 | DI6: 0 | DJ6: 0 | DK6: 0 | DL6: 0 | DM6: 0 | DN6: 0 | DO6: 0 | DP6: 0 | DQ6: 0 | DR6: 0 | DS6: 0 | DT6: 0 | DU6: 0 | DV6: 0 | DW6: 0 | DX6: 0 | DY6: 0 | DZ6: 0 | EA6: 0 | EB6: 0 | EC6: 0 | ED6: 0 | EE6: 0 | EF6: 0 | EG6: 0 | EH6: 0 | EI6: 0 | EJ6: 0 | EK6: 0 | EL6: 0 | EM6: 0 | EN6: 0 | EO6: 0 | EP6: 0 | EQ6: 0 | ER6: 0 | ES6: 0 | ET6: 0 | EU6: 0 | EV6: 0 | EW6: 0 | EX6: 0 | EY6: 0 | EZ6: 0 | FA6: 0 | FB6: 0 | FC6: 0 | FD6: 0 | FE6: 0 | FF6: 0 | FG6: 0 | FH6: 0 | FI6: 0 | FJ6: 0 | FK6: 0 | FL6: 0 | FM6: 0 | FN6: 0 | FO6: 0 | FP6: 0 | FQ6: 0 | FR6: 0 | FS6: 0 | FT6: 0 | FU6: 0 | FV6: 0 | FW6: 0 | FX6: 0 | FY6: 0 | FZ6: 0 | GA6: 0 | GB6: 0 | GC6: 0 | GD6: 0 | GE6: 0 | GF6: 0 | GG6: 0 | GH6: 0 | GI6: 0 | GJ6: 0 | GK6: 0 | GL6: 0 | GM6: 0 | GN6: 0 | GO6: 0 | GP6: 0 | GQ6: 0 | GR6: 0 | GS6: 0 | GT6: 0 | GU6: 0 | GV6: 0 | GW6: 0 | GX6: 0 | GY6: 0 | GZ6: 0 | HA6: 0 | HB6: 0 | HC6: 0 | HD6: 0 | HE6: 0 | HF6: 0 | HG6: 0 | HH6: 0 | HI6: 0 | HJ6: 0 | HK6: 0 | HL6: 0 | HM6: 0 | HN6: 0 | HO6: 0 | HP6: 0 | HQ6: 0 | HR6: 0 | HS6: 0 | HT6: 0 | HU6: 0 | HV6: 0 | HW6: 0 | HX6: 0 | HY6: 0 | HZ6: 0 | IA6: 0 | IB6: 0 | IC6: 0 | ID6: 0 | IE6: 0 | IF6: 0 | IG6: 0 | IH6: 0 | II6: 0 | IJ6: 0 | IK6: 0 | IL6: 0 | IM6: 0 | IN6: 0 | IO6: 0 | IP6: 0 | IQ6: 0 | IR6: 0 | IS6: 0 | IT6: 0 | IU6: 0 | IV6: 0 | IW6: 0 | IX6: 0 | IY6: 0 | IZ6: 0 | JA6: 0 | JB6: 0 | JC6: 0 | JD6: 0 | JE6: 0 | JF6: 0 | JG6: 0 | JH6: 0 | JI6: 0 | JJ6: 0 | JK6: 0 | JL6: 0 | JM6: 0 | JN6: 0 | JO6: 0 | JP6: 0 | JQ6: 0 | JR6: 0 | JS6: 0 | JT6: 0 | JU6: 0 | JV6: 0 | JW6: 0 | JX6: 0 | JY6: 0 | JZ6: 0 | KA6: 0 | KB6: 0 | KC6: 0 | KD6: 0 | KE6: 0 | KF6: 0 | KG6: 0 | KH6: 0 | KI6: 0 | KJ6: 0 | KK6: 0 | KL6: 0 | KM6: 0 | KN6: 0 | KO6: 0 | KP6: 0 | KQ6: 0 | KR6: 0 | KS6: 0 | KT6: 0 | KU6: 0 | KV6: 0 | KW6: 0 | KX6: 0 | KY6: 0 | KZ6: 0 | LA6: 0 | LB6: 0 | LC6: 0 | LD6: 0 | LE6: 0 | LF6: 0 | LG6: 0 | LH6: 0 | LI6: 0 | LJ6: 0 | LK6: 0 | LL6: 0 | LM6: 0 | LN6: 0 | LO6: 0 | LP6: 0 | LQ6: 0 | LR6: 0 | LS6: 0 | LT6: 0 | LU6: 0 | LV6: 0 | LW6: 0 | LX6: 0 | LY6: 0 | LZ6: 0 | MA6: 0 | MB6: 0 | MC6: 0 | MD6: 0 | ME6: 0 | MF6: 0 | MG6: 0 | MH6: 0 | MI6: 0 | MJ6: 0 | MK6: 0 | ML6: 0 | MM6: 0 | MN6: 0 | MO6: 0 | MP6: 0 | MQ6: 0 | MR6: 0 | MS6: 0 | MT6: 0 | MU6: 0 | MV6: 0 | MW6: 0 | MX6: 0 | MY6: 0 | MZ6: 0 | NA6: 0 | NB6: 0 | NC6: 0 | ND6: 0 | NE6: 0 | NF6: 0 | NG6: 0 | NH6: 0 | NI6: 0 | NJ6: 0 | NK6: 0 | NL6: 0 | NM6: 0 | NN6: 0 | NO6: 0 | NP6: 0 | NQ6: 0 | NR6: 0 | NS6: 0 | NT6: 0 | NU6: 0 | NV6: 0 | NW6: 0 | NX6: 0 | NY6: 0 | NZ6: 0 | OA6: 0 | OB6: 0 | OC6: 0 | OD6: 0 | OE6: 0 | OF6: 0 | OG6: 0 | OH6: 0 | OI6: 0 | OJ6: 0 | OK6: 0 | OL6: 0 | OM6: 0 | ON6: 0 | OO6: 0 | OP6: 0 | OQ6: 0 | OR6: 0 | OS6: 0 | OT6: 0 | OU6: 0 | OV6: 0 | OW6: 0 | OX6: 0 | OY6: 0 | OZ6: 0 | PA6: 0 | PB6: 0 | PC6: 0 | PD6: 0 | PE6: 0 | PF6: 0 | PG6: 0 | PH6: 0 | PI6: 0 | PJ6: 0 | PK6: 0 | PL6: 0 | PM6: 0 | PN6: 0 | PO6: 0 | PP6: 0 | PQ6: 0 | PR6: 0 | PS6: 0 | PT6: 0 | PU6: 0 | PV6: 0 | PW6: 0 | PX6: 0 | PY6: 0 | PZ6: 0 | QA6: 0 | QB6: 0 | QC6: 0 | QD6: 0 | QE6: 0 | QF6: 0 | QG6: 0 | QH6: 0 | QI6: 0 | QJ6: 0 | QK6: 0 | QL6: 0 | QM6: 0 | QN6: 0 | QO6: 0 | QP6: 0 | QQ6: 0 | QR6: 0 | QS6: 0 | QT6: 0 | QU6: 0 | QV6: 0 | QW6: 0 | QX6: 0 | QY6: 0 | QZ6: 0 | RA6: 0 | RB6: 0 | RC6: 0 | RD6: 0 | RE6: 0 | RF6: 0 | RG6: 0 | RH6: 0 | RI6: 0 | RJ6: 0 | RK6: 0 | RL6: 0 | RM6: 0 | RN6: 0 | RO6: 0 | RP6: 0 | RQ6: 0 | RR6: 0 | RS6: 0 | RT6: 0 | RU6: 0 | RV6: 0 | RW6: 0 | RX6: 0 | RY6: 0 | RZ6: 0 | SA6: 0 | SB6: 0 | SC6: 0 | SD6: 0 | SE6: 0 | SF6: 0
B7: 0 | C7: 12800025601141416 | D7: 黎明灰 | E7: 150*200cm | F7: 0 | G7: 0 | H7: 0 | I7: 0 | J7: 2 | K7: 74 | L7: 62 | M7: 0 | N7: 0 | O7: 78 | P7: 118 | Q7: 0 | R7: 107 | S7: 139 | T7: 158 | U7: 0 | V7: 336 | W7: 32 | X7: 29 | Y7: 80 | Z7: 0 | AA7: 39 | AB7: 76 | AC7: 40 | AD7: 142 | AE7: 22 | AF7: 59 | AG7: 0 | AH7: 0 | AI7: 271 | AJ7: 95 | AK7: 0 | AL7: 17 | AM7: 53 | AN7: 27 | AO7: 34 | AP7: 31 | AQ7: 0 | AR7: 0 | AS7: 0 | AT7: 99 | AU7: 0 | AV7: 112 | AW7: 23 | AX7: 53 | AY7: 54 | AZ7: 18 | BA7: 32 | BB7: 462 | BC7: 272 | BD7: 307 | BE7: 67 | BF7: 73 | BG7: 6 | BH7: 93 | BI7: 86 | BJ7: 167 | BK7: 0 | BL7: 180 | BM7: 0 | BN7: 179 | BO7: 358 | BP7: 212 | BQ7: 34 | BR7: 0 | BS7: 0 | BT7: 91 | BU7: 128 | BV7: 7 | BW7: 0 | BX7: 0 | BY7: 0 | BZ7: 0 | CA7: 0 | CB7: 0 | CC7: 5 | CD7: 0 | CE7: 48 | CF7: 15 | CG7: 0 | CH7: 0 | CI7: 0 | CJ7: 38 | CK7: 0 | CL7: 0 | CM7: 0 | CN7: 0 | CO7: 49 | CP7: 0 | CQ7: 0 | CR7: 0 | CS7: 0 | CT7: 0 | CU7: 0 | CV7: 0 | CW7: 0 | CX7: 0 | CY7: 0 | CZ7: 0 | DA7: 0 | DB7: 0 | DC7: 0 | DD7: 0 | DE7: 0 | DF7: 0 | DG7: 0 | DH7: 0 | DI7: 0 | DJ7: 0 | DK7: 0 | DL7: 0 | DM7: 0 | DN7: 0 | DO7: 0 | DP7: 0 | DQ7: 0 | DR7: 0 | DS7: 0 | DT7: 0 | DU7: 0 | DV7: 0 | DW7: 0 | DX7: 0 | DY7: 0 | DZ7: 0 | EA7: 0 | EB7: 0 | EC7: 0 | ED7: 0 | EE7: 0 | EF7: 0 | EG7: 0 | EH7: 0 | EI7: 0 | EJ7: 0 | EK7: 0 | EL7: 0 | EM7: 0 | EN7: 0 | EO7: 0 | EP7: 0 | EQ7: 0 | ER7: 0 | ES7: 0 | ET7: 0 | EU7: 0 | EV7: 0 | EW7: 0 | EX7: 0 | EY7: 0 | EZ7: 0 | FA7: 0 | FB7: 0 | FC7: 0 | FD7: 0 | FE7: 0 | FF7: 0 | FG7: 0 | FH7: 0 | FI7: 0 | FJ7: 0 | FK7: 0 | FL7: 0 | FM7: 0 | FN7: 0 | FO7: 0 | FP7: 0 | FQ7: 0 | FR7: 0 | FS7: 0 | FT7: 0 | FU7: 0 | FV7: 0 | FW7: 0 | FX7: 0 | FY7: 0 | FZ7: 0 | GA7: 0 | GB7: 0 | GC7: 0 | GD7: 0 | GE7: 0 | GF7: 0 | GG7: 0 | GH7: 0 | GI7: 0 | GJ7: 0 | GK7: 0 | GL7: 0 | GM7: 0 | GN7: 0 | GO7: 0 | GP7: 0 | GQ7: 0 | GR7: 0 | GS7: 0 | GT7: 0 | GU7: 0 | GV7: 0 | GW7: 0 | GX7: 0 | GY7: 0 | GZ7: 0 | HA7: 0 | HB7: 0 | HC7: 0 | HD7: 0 | HE7: 0 | HF7: 0 | HG7: 0 | HH7: 0 | HI7: 0 | HJ7: 0 | HK7: 0 | HL7: 0 | HM7: 0 | HN7: 0 | HO7: 0 | HP7: 0 | HQ7: 0 | HR7: 0 | HS7: 0 | HT7: 0 | HU7: 0 | HV7: 0 | HW7: 0 | HX7: 0 | HY7: 0 | HZ7: 0 | IA7: 0 | IB7: 0 | IC7: 0 | ID7: 0 | IE7: 0 | IF7: 0 | IG7: 0 | IH7: 0 | II7: 0 | IJ7: 0 | IK7: 0 | IL7: 0 | IM7: 0 | IN7: 0 | IO7: 0 | IP7: 0 | IQ7: 0 | IR7: 0 | IS7: 0 | IT7: 0 | IU7: 0 | IV7: 0 | IW7: 0 | IX7: 0 | IY7: 0 | IZ7: 0 | JA7: 0 | JB7: 0 | JC7: 0 | JD7: 0 | JE7: 0 | JF7: 0 | JG7: 0 | JH7: 0 | JI7: 0 | JJ7: 0 | JK7: 0 | JL7: 0 | JM7: 0 | JN7: 0 | JO7: 0 | JP7: 0 | JQ7: 0 | JR7: 0 | JS7: 0 | JT7: 0 | JU7: 0 | JV7: 0 | JW7: 0 | JX7: 0 | JY7: 0 | JZ7: 0 | KA7: 0 | KB7: 0 | KC7: 0 | KD7: 0 | KE7: 0 | KF7: 0 | KG7: 0 | KH7: 0 | KI7: 0 | KJ7: 0 | KK7: 0 | KL7: 0 | KM7: 0 | KN7: 0 | KO7: 0 | KP7: 0 | KQ7: 0 | KR7: 0 | KS7: 0 | KT7: 0 | KU7: 0 | KV7: 0 | KW7: 0 | KX7: 0 | KY7: 0 | KZ7: 0 | LA7: 0 | LB7: 0 | LC7: 0 | LD7: 0 | LE7: 0 | LF7: 0 | LG7: 0 | LH7: 0 | LI7: 0 | LJ7: 0 | LK7: 0 | LL7: 0 | LM7: 0 | LN7: 0 | LO7: 0 | LP7: 0 | LQ7: 0 | LR7: 0 | LS7: 0 | LT7: 0 | LU7: 0 | LV7: 0 | LW7: 0 | LX7: 0 | LY7: 0 | LZ7: 0 | MA7: 0 | MB7: 0 | MC7: 0 | MD7: 0 | ME7: 0 | MF7: 0 | MG7: 0 | MH7: 0 | MI7: 0 | MJ7: 0 | MK7: 0 | ML7: 0 | MM7: 0 | MN7: 0 | MO7: 0 | MP7: 0 | MQ7: 0 | MR7: 0 | MS7: 0 | MT7: 0 | MU7: 0 | MV7: 0 | MW7: 0 | MX7: 0 | MY7: 0 | MZ7: 0 | NA7: 0 | NB7: 0 | NC7: 0 | ND7: 0 | NE7: 0 | NF7: 0 | NG7: 0 | NH7: 0 | NI7: 0 | NJ7: 0 | NK7: 0 | NL7: 0 | NM7: 0 | NN7: 0 | NO7: 0 | NP7: 0 | NQ7: 0 | NR7: 0 | NS7: 0 | NT7: 0 | NU7: 0 | NV7: 0 | NW7: 0 | NX7: 0 | NY7: 0 | NZ7: 0 | OA7: 0 | OB7: 0 | OC7: 0 | OD7: 0 | OE7: 0 | OF7: 0 | OG7: 0 | OH7: 0 | OI7: 0 | OJ7: 0 | OK7: 0 | OL7: 0 | OM7: 0 | ON7: 0 | OO7: 0 | OP7: 0 | OQ7: 0 | OR7: 0 | OS7: 0 | OT7: 0 | OU7: 0 | OV7: 0 | OW7: 0 | OX7: 0 | OY7: 0 | OZ7: 0 | PA7: 0 | PB7: 0 | PC7: 0 | PD7: 0 | PE7: 0 | PF7: 0 | PG7: 0 | PH7: 0 | PI7: 0 | PJ7: 0 | PK7: 0 | PL7: 0 | PM7: 0 | PN7: 0 | PO7: 0 | PP7: 0 | PQ7: 0 | PR7: 0 | PS7: 0 | PT7: 0 | PU7: 0 | PV7: 0 | PW7: 0 | PX7: 0 | PY7: 0 | PZ7: 0 | QA7: 0 | QB7: 0 | QC7: 0 | QD7: 0 | QE7: 0 | QF7: 0 | QG7: 0 | QH7: 0 | QI7: 0 | QJ7: 0 | QK7: 0 | QL7: 0 | QM7: 0 | QN7: 0 | QO7: 0 | QP7: 0 | QQ7: 0 | QR7: 0 | QS7: 0 | QT7: 0 | QU7: 0 | QV7: 0 | QW7: 0 | QX7: 0 | QY7: 0 | QZ7: 0 | RA7: 0 | RB7: 0 | RC7: 0 | RD7: 0 | RE7: 0 | RF7: 0 | RG7: 0 | RH7: 0 | RI7: 0 | RJ7: 0 | RK7: 0 | RL7: 0 | RM7: 0 | RN7: 0 | RO7: 0 | RP7: 0 | RQ7: 0 | RR7: 0 | RS7: 0 | RT7: 0 | RU7: 0 | RV7: 0 | RW7: 0 | RX7: 0 | RY7: 0 | RZ7: 0 | SA7: 0 | SB7: 0 | SC7: 0 | SD7: 0 | SE7: 0 | SF7: 0
